Workbook

Sheet Th_CSE
A1: Indian Institute of Information Technology (IIIT), Surat
A2: Computer Science and Engineering Department
A3: B.Tech - III Semester - V
A4: Subject Name:- Could Computing and Big data infrastructure (CS- 504)
A5: Subject Coordinator:
A6: Academic Year: 2025-2026
D8: July | E8: Aug | I8: OCT | P8: Nov | AC8: Total P | AD8: Total A | AE8: Total | AF8: %
D9: 31 | E9: 1 | F9: 09/08 | G9: 09/08 | H9: 11/08 | I9: 16/08 | J9: 16/08 | K9: 21/08 | L9: 23/08 | M9: 23/08 | N9: 30/08 | O9: 30/08 | P9: 27/09 | Q9: 27/09 | R9: 04/10 | S9: 04/10 | T9: 06/10 | U9: 11/10 | V9: 11/10 | W9: 01/10 | X9: 01/11 | Y9: 01/11
A10: Sr. No | B10: Enrollment No. | C10: Name | D10: 1 | E10: 2 | F10: 3 | G10: 4 | H10: 5 | I10: 6 | J10: 7 | K10: 8 | L10: 9 | M10: 10 | N10: 11 | O10: 12 | P10: 13 | Q10: 14 | R10: 15 | S10: 16 | T10: 17 | U10: 18 | V10: 19 | W10: 20 | X10: 21 | Y10: 22
A11: 1 | B11: UI23CS01 | C11: ABHINAV | D11: A | E11: P | F11: P | G11: P | H11: P | I11: A | J11: A | K11: A | L11: P | M11: P | N11: P | O11: A | P11: P | Q11: P | R11: A | S11: A | T11: A | U11: P | V11: P | W11: P | X11: P | Y11: P | AC11: =COUNTIF(D11:AB11,"P") + COUNTIF(D11:AB11, "1") -> 14 | AD11: =COUNTIF(D11:AB11,"A") + COUNTIF(D11:AB11,"0") -> 8 | AE11: =SUM(AC11:AD11) -> 22 | AF11: =(AC11/AE11)*100 -> 63.636364
A12: 2 | B12: UI23CS02 | C12: ABHISHEK YADAV | D12: P | E12: P | F12: P | G12: P | H12: P | I12: P | J12: P | K12: P | L12: P | M12: P | N12: A | O12: P | P12: P | Q12: P | R12: P | S12: A | T12: P | U12: P | V12: P | W12: P | X12: P | Y12: P | AC12: =COUNTIF(D12:AB12,"P") + COUNTIF(D12:AB12, "1") -> 20 | AD12: =COUNTIF(D12:AB12,"A") + COUNTIF(D12:AB12,"0") -> 2 | AE12: =SUM(AC12:AD12) -> 22 | AF12: =(AC12/AE12)*100 -> 90.909091
A13: 3 | B13: UI23CS03 | C13: AKHILESH SINGH | D13: A | E13: P | F13: A | G13: P | H13: P | I13: P | J13: P | K13: A | L13: P | M13: P | N13: P | O13: A | P13: A | Q13: A | R13: P | S13: P | T13: A | U13: A | V13: A | W13: A | X13: A | Y13: A | AC13: =COUNTIF(D13:AB13,"P") + COUNTIF(D13:AB13, "1") -> 10 | AD13: =COUNTIF(D13:AB13,"A") + COUNTIF(D13:AB13,"0") -> 12 | AE13: =SUM(AC13:AD13) -> 22 | AF13: =(AC13/AE13)*100 -> 45.454545
A14: 4 | B14: UI23CS05 | C14: AMAN DUDI | D14: P | E14: P | F14: P | G14: P | H14: A | I14: P | J14: P | K14: A | L14: P | M14: P | N14: P | O14: A | P14: P | Q14: P | R14: P | S14: P | T14: P | U14: P | V14: P | W14: P | X14: P | Y14: P | AC14: =COUNTIF(D14:AB14,"P") + COUNTIF(D14:AB14, "1") -> 19 | AD14: =COUNTIF(D14:AB14,"A") + COUNTIF(D14:AB14,"0") -> 3 | AE14: =SUM(AC14:AD14) -> 22 | AF14: =(AC14/AE14)*100 -> 86.363636
A15: 5 | B15: UI23CS06 | C15: AMAN KUMAR | D15: P | E15: P | F15: P | G15: P | H15: P | I15: A | J15: A | K15: A | L15: A | M15: A | N15: P | O15: A | P15: A | Q15: A | R15: P | S15: P | T15: P | U15: P | V15: P | W15: P | X15: P | Y15: P | AC15: =COUNTIF(D15:AB15,"P") + COUNTIF(D15:AB15, "1") -> 14 | AD15: =COUNTIF(D15:AB15,"A") + COUNTIF(D15:AB15,"0") -> 8 | AE15: =SUM(AC15:AD15) -> 22 | AF15: =(AC15/AE15)*100 -> 63.636364
A16: 6 | B16: UI23CS07 | C16: ANJALI | D16: P | E16: P | F16: P | G16: P | H16: A | I16: P | J16: P | K16: A | L16: P | M16: P | N16: P | O16: P | P16: P | Q16: P | R16: P | S16: P | T16: A | U16: P | V16: P | W16: P | X16: P | Y16: P | AC16: =COUNTIF(D16:AB16,"P") + COUNTIF(D16:AB16, "1") -> 19 | AD16: =COUNTIF(D16:AB16,"A") + COUNTIF(D16:AB16,"0") -> 3 | AE16: =SUM(AC16:AD16) -> 22 | AF16: =(AC16/AE16)*100 -> 86.363636
A17: 7 | B17: UI23CS08 | C17: ANUBHAV RAJPUT | D17: A | E17: P | F17: P | G17: P | H17: A | I17: P | J17: P | K17: A | L17: P | M17: P | N17: P | O17: P | P17: P | Q17: P | R17: A | S17: A | T17: P | U17: P | V17: P | W17: P | X17: P | Y17: P | AC17: =COUNTIF(D17:AB17,"P") + COUNTIF(D17:AB17, "1") -> 17 | AD17: =COUNTIF(D17:AB17,"A") + COUNTIF(D17:AB17,"0") -> 5 | AE17: =SUM(AC17:AD17) -> 22 | AF17: =(AC17/AE17)*100 -> 77.272727
A18: 8 | B18: UI23CS09 | C18: AVIRAL PANDEY | D18: P | E18: P | F18: P | G18: P | H18: P | I18: P | J18: P | K18: P | L18: P | M18: P | N18: P | O18: P | P18: A | Q18: A | R18: P | S18: P | T18: P | U18: P | V18: P | W18: P | X18: P | Y18: P | AC18: =COUNTIF(D18:AB18,"P") + COUNTIF(D18:AB18, "1") -> 20 | AD18: =COUNTIF(D18:AB18,"A") + COUNTIF(D18:AB18,"0") -> 2 | AE18: =SUM(AC18:AD18) -> 22 | AF18: =(AC18/AE18)*100 -> 90.909091
A19: 9 | B19: UI23CS10 | C19: BAPATHI VENKATA SHV REDDY | D19: A | E19: P | F19: P | G19: P | H19: P | I19: P | J19: P | K19: P | L19: A | M19: A | N19: P | O19: A | P19: A | Q19: A | R19: A | S19: A | T19: P | U19: P | V19: P | W19: P | X19: P | Y19: P | AC19: =COUNTIF(D19:AB19,"P") + COUNTIF(D19:AB19, "1") -> 14 | AD19: =COUNTIF(D19:AB19,"A") + COUNTIF(D19:AB19,"0") -> 8 | AE19: =SUM(AC19:AD19) -> 22 | AF19: =(AC19/AE19)*100 -> 63.636364
A20: 10 | B20: UI23CS11 | C20: BELLAM APOORVA | D20: P | E20: P | F20: P | G20: P | H20: P | I20: P | J20: P | K20: A | L20: P | M20: P | N20: P | O20: P | P20: P | Q20: P | R20: P | S20: P | T20: A | U20: P | V20: P | W20: P | X20: P | Y20: P | AC20: =COUNTIF(D20:AB20,"P") + COUNTIF(D20:AB20, "1") -> 20 | AD20: =COUNTIF(D20:AB20,"A") + COUNTIF(D20:AB20,"0") -> 2 | AE20: =SUM(AC20:AD20) -> 22 | AF20: =(AC20/AE20)*100 -> 90.909091
A21: 11 | B21: UI23CS12 | C21: BHUKYA LINGANNA | D21: A | E21: P | F21: P | G21: A | H21: A | I21: P | J21: P | K21: A | L21: P | M21: P | N21: P | O21: P | P21: P | Q21: P | R21: P | S21: P | T21: P | U21: P | V21: P | W21: P | X21: P | Y21: P | AC21: =COUNTIF(D21:AB21,"P") + COUNTIF(D21:AB21, "1") -> 18 | AD21: =COUNTIF(D21:AB21,"A") + COUNTIF(D21:AB21,"0") -> 4 | AE21: =SUM(AC21:AD21) -> 22 | AF21: =(AC21/AE21)*100 -> 81.818182
A22: 12 | B22: UI23CS13 | C22: BHUPENDRA KUMAR | D22: P | E22: P | F22: P | G22: P | H22: P | I22: A | J22: A | K22: P | L22: P | M22: P | N22: P | O22: P | P22: P | Q22: P | R22: P | S22: P | T22: P | U22: P | V22: P | W22: P | X22: P | Y22: P | AC22: =COUNTIF(D22:AB22,"P") + COUNTIF(D22:AB22, "1") -> 20 | AD22: =COUNTIF(D22:AB22,"A") + COUNTIF(D22:AB22,"0") -> 2 | AE22: =SUM(AC22:AD22) -> 22 | AF22: =(AC22/AE22)*100 -> 90.909091
... A82: 72 | B82: UI23CS77 | C82: VIVEK BAYA | D82: P | E82: P | F82: P | G82: P | H82: P | I82: P | J82: P | K82: A | L82: P | M82: P | N82: A | O82: P | P82: P | Q82: P | R82: P | S82: P | T82: P | U82: A | V82: A | W82: P | X82: P | Y82: P | AC82: =COUNTIF(D82:AB82,"P") + COUNTIF(D82:AB82, "1") -> 18 | AD82: =COUNTIF(D82:AB82,"A") + COUNTIF(D82:AB82,"0") -> 4 | AE82: =SUM(AC82:AD82) -> 22 | AF82: =(AC82/AE82)*100 -> 81.818182
A83: 73 | B83: UI23CS78 | C83: YUG PATEL | D83: P | E83: P | AC83: =COUNTIF(D83:AB83,"P") + COUNTIF(D83:AB83, "1") -> 2 | AD83: =COUNTIF(D83:AB83,"A") + COUNTIF(D83:AB83,"0") -> 0 | AE83: =SUM(AC83:AD83) -> 2 | AF83: =(AC83/AE83)*100 -> 100
A84: 74 | B84: UI22CS11 | C84: BANOTH VENKATESH | D84: P | E84: P | AC84: =COUNTIF(D84:AB84,"P") + COUNTIF(D84:AB84, "1") -> 2 | AD84: =COUNTIF(D84:AB84,"A") + COUNTIF(D84:AB84,"0") -> 0 | AE84: =SUM(AC84:AD84) -> 2 | AF84: =(AC84/AE84)*100 -> 100
C88: No. of Present Student | T88: =COUNTIF(T11:T87,"P") + COUNTIF(T11:T87, "1") -> 60 | U88: =COUNTIF(U11:U87,"P") + COUNTIF(U11:U87, "1") -> 60 | W88: =COUNTIF(W11:W87,"P") + COUNTIF(W11:W87, "1") -> 66 | X88: =COUNTIF(X11:X87,"P") + COUNTIF(X11:X87, "1") -> 66 | Y88: =COUNTIF(Y11:Y87,"P") + COUNTIF(Y11:Y87, "1") -> 66 | Z88: =COUNTIF(Z11:Z87,"P") + COUNTIF(Z11:Z87, "1") -> 0 | AA88: =COUNTIF(AA11:AA87,"P") + COUNTIF(AA11:AA87, "1") -> 0 | AB88: =COUNTIF(AB11:AB87,"P") + COUNTIF(AB11:AB87, "1") -> 0
C89: No. of Absent Student | D89: =COUNTIF(D11:D87,"A") + COUNTIF(D11:D87, "1") -> 6 | E89: =COUNTIF(E11:E87,"A") + COUNTIF(E11:E87, "1") -> 1 | F89: =COUNTIF(F11:F87,"A") + COUNTIF(F11:F87, "1") -> 11 | G89: =COUNTIF(G11:G87,"A") + COUNTIF(G11:G87, "1") -> 13 | H89: =COUNTIF(H11:H87,"A") + COUNTIF(H11:H87, "1") -> 11 | I89: =COUNTIF(I11:I87,"A") + COUNTIF(I11:I87, "1") -> 25 | J89: =COUNTIF(J11:J87,"A") + COUNTIF(J11:J87, "1") -> 25 | K89: =COUNTIF(K11:K87,"A") + COUNTIF(K11:K87, "1") -> 26 | ... U89: =COUNTIF(U11:U87,"A") + COUNTIF(U11:U87, "1") -> 12 | W89: =COUNTIF(W11:W87,"A") + COUNTIF(W11:W87, "1") -> 6 | X89: =COUNTIF(X11:X87,"A") + COUNTIF(X11:X87, "1") -> 6 | Y89: =COUNTIF(Y11:Y87,"A") + COUNTIF(Y11:Y87, "1") -> 6 | Z89: =COUNTIF(Z11:Z87,"A") + COUNTIF(Z11:Z87, "1") -> 0 | AA89: =COUNTIF(AA11:AA87,"A") + COUNTIF(AA11:AA87, "1") -> 0 | AB89: =COUNTIF(AB11:AB87,"A") + COUNTIF(AB11:AB87, "1") -> 0

Sheet Th_ECE
A1: Indian Institute of Information Technology (IIIT), Surat
A3: B.Tech - III Semester - V
A4: Subject Name:- Could Computing and Big data infrastructure (CS- 504)
A5: Subject Coordinator:
A6: Academic Year: 2025-2026
Z8: Total P | AA8: Total A | AB8: Total | AC8: Present
D10: 1 | E10: 09/08 | F10: 09/08 | G10: 11/08 | H10: 16/08 | I10: 16/08 | J10: 21/08 | K10: 23/08 | L10: 23/08 | M10: 30/08 | N10: 30/08 | O10: 27/09 | P10: 27/09 | Q10: 04/10 | R10: 04/10 | S10: 06/10 | T10: 11/10 | U10: 11/10 | V10: 01/11 | W10: 01/11 | X10: 01/11
A11: Sr. No | B11: Enrollment No. | C11: Name | D11: 1 | E11: 3 | F11: 4 | G11: 5 | H11: 6 | I11: 7 | J11: 8 | K11: 9 | L11: 10 | M11: 11 | N11: 12 | O11: 13 | P11: 14 | Q11: 15 | R11: 16 | S11: 17 | T11: 18 | U11: 19 | V11: 20 | W11: 21 | X11: 22
A12: 1 | B12: UI23EC01 | C12: ABHAY JAISWAL | D12: P | E12: P | F12: P | G12: P | H12: A | I12: A | J12: P | K12: A | L12: A | M12: P | N12: P | O12: P | P12: P | Q12: A | R12: A | S12: P | T12: P | U12: P | V12: P | W12: P | X12: P | Z12: =COUNTIF(D12:Y12,"P") + COUNTIF(D12:Y12, "1") -> 15 | AA12: =COUNTIF(D12:Y12,"A") + COUNTIF(D12:Y12,"0") -> 6 | AB12: =SUM(Z12:AA12) -> 21 | AC12: =(Z12/AB12)*100 -> 71.428571
A13: 2 | B13: UI23EC02 | C13: ADARSH PANDEY | D13: P | E13: P | F13: P | G13: P | H13: A | I13: A | J13: A | K13: A | L13: A | M13: P | N13: P | O13: P | P13: P | Q13: P | R13: P | S13: P | T13: P | U13: P | V13: P | W13: P | X13: P | Z13: =COUNTIF(D13:Y13,"P") + COUNTIF(D13:Y13, "1") -> 16 | AA13: =COUNTIF(D13:Y13,"A") + COUNTIF(D13:Y13,"0") -> 5 | AB13: =SUM(Z13:AA13) -> 21 | AC13: =(Z13/AB13)*100 -> 76.190476
A14: 3 | B14: UI23EC03 | C14: ADITYA ANAND | D14: P | E14: P | F14: P | G14: P | H14: A | I14: A | J14: P | K14: P | L14: P | M14: P | N14: P | O14: P | P14: P | Q14: P | R14: P | S14: P | T14: P | U14: P | V14: P | W14: P | X14: P | Z14: =COUNTIF(D14:Y14,"P") + COUNTIF(D14:Y14, "1") -> 19 | AA14: =COUNTIF(D14:Y14,"A") + COUNTIF(D14:Y14,"0") -> 2 | AB14: =SUM(Z14:AA14) -> 21 | AC14: =(Z14/AB14)*100 -> 90.47619
A15: 4 | B15: UI23EC04 | C15: ANKIT KUMAR | D15: A | E15: P | F15: A | G15: A | H15: A | I15: A | J15: P | K15: P | L15: P | M15: A | N15: A | O15: P | P15: P | Q15: P | R15: P | S15: P | T15: P | U15: P | V15: P | W15: P | X15: P | Z15: =COUNTIF(D15:Y15,"P") + COUNTIF(D15:Y15, "1") -> 14 | AA15: =COUNTIF(D15:Y15,"A") + COUNTIF(D15:Y15,"0") -> 7 | AB15: =SUM(Z15:AA15) -> 21 | AC15: =(Z15/AB15)*100 -> 66.666667
A16: 5 | B16: UI23EC06 | C16: ARPIT CHAUHAN | D16: A | E16: P | F16: P | G16: A | H16: P | I16: P | J16: P | K16: A | L16: A | M16: P | N16: P | O16: P | P16: P | Q16: A | R16: A | S16: P | T16: P | U16: P | V16: P | W16: P | X16: P | Z16: =COUNTIF(D16:Y16,"P") + COUNTIF(D16:Y16, "1") -> 15 | AA16: =COUNTIF(D16:Y16,"A") + COUNTIF(D16:Y16,"0") -> 6 | AB16: =SUM(Z16:AA16) -> 21 | AC16: =(Z16/AB16)*100 -> 71.428571
A17: 6 | B17: UI23EC07 | C17: ARPIT KHARE | D17: P | E17: P | F17: P | G17: P | H17: A | I17: A | J17: P | K17: P | L17: P | M17: P | N17: P | O17: P | P17: P | Q17: A | R17: A | S17: P | T17: A | U17: A | V17: P | W17: P | X17: P | Z17: =COUNTIF(D17:Y17,"P") + COUNTIF(D17:Y17, "1") -> 15 | AA17: =COUNTIF(D17:Y17,"A") + COUNTIF(D17:Y17,"0") -> 6 | AB17: =SUM(Z17:AA17) -> 21 | AC17: =(Z17/AB17)*100 -> 71.428571
A18: 7 | B18: UI23EC08 | C18: ARYAN KUMAR | D18: P | E18: P | F18: P | G18: P | H18: P | I18: P | J18: P | K18: A | L18: P | M18: A | N18: A | O18: P | P18: P | Q18: P | R18: P | S18: P | T18: P | U18: P | V18: A | W18: A | X18: A | Z18: =COUNTIF(D18:Y18,"P") + COUNTIF(D18:Y18, "1") -> 15 | AA18: =COUNTIF(D18:Y18,"A") + COUNTIF(D18:Y18,"0") -> 6 | AB18: =SUM(Z18:AA18) -> 21 | AC18: =(Z18/AB18)*100 -> 71.428571
A19: 8 | B19: UI23EC09 | C19: ARYAN TIWARI | D19: P | E19: A | F19: A | G19: A | H19: A | I19: A | J19: P | K19: P | L19: P | M19: P | N19: P | O19: P | P19: P | Q19: P | R19: P | S19: P | T19: P | U19: P | V19: P | W19: P | X19: P | Z19: =COUNTIF(D19:Y19,"P") + COUNTIF(D19:Y19, "1") -> 16 | AA19: =COUNTIF(D19:Y19,"A") + COUNTIF(D19:Y19,"0") -> 5 | AB19: =SUM(Z19:AA19) -> 21 | AC19: =(Z19/AB19)*100 -> 76.190476
A20: 9 | B20: UI23EC11 | C20: AYUSH SINGH | D20: P | E20: P | F20: P | G20: A | H20: P | I20: P | J20: P | K20: A | L20: A | M20: A | N20: P | O20: P | P20: P | Q20: A | R20: A | S20: P | T20: P | U20: P | V20: P | W20: P | X20: P | Z20: =COUNTIF(D20:Y20,"P") + COUNTIF(D20:Y20, "1") -> 15 | AA20: =COUNTIF(D20:Y20,"A") + COUNTIF(D20:Y20,"0") -> 6 | AB20: =SUM(Z20:AA20) -> 21 | AC20: =(Z20/AB20)*100 -> 71.428571
A21: 10 | B21: UI23EC12 | C21: BODDU SRINIVASA RAO | D21: P | E21: P | F21: P | G21: P | H21: P | I21: P | J21: P | K21: A | L21: A | M21: P | N21: P | O21: A | P21: A | Q21: P | R21: P | S21: P | T21: A | U21: A | V21: P | W21: P | X21: P | Z21: =COUNTIF(D21:Y21,"P") + COUNTIF(D21:Y21, "1") -> 15 | AA21: =COUNTIF(D21:Y21,"A") + COUNTIF(D21:Y21,"0") -> 6 | AB21: =SUM(Z21:AA21) -> 21 | AC21: =(Z21/AB21)*100 -> 71.428571
A22: 11 | B22: UI23EC13 | C22: CHETHAN SAI BILLA | D22: P | E22: P | F22: P | G22: P | H22: P | I22: P | J22: P | K22: A | L22: P | M22: A | N22: P | O22: P | Q22: P | R22: P | S22: P | T22: P | U22: P | V22: P | W22: P | X22: P | Z22: =COUNTIF(D22:Y22,"P") + COUNTIF(D22:Y22, "1") -> 18 | AA22: =COUNTIF(D22:Y22,"A") + COUNTIF(D22:Y22,"0") -> 2 | AB22: =SUM(Z22:AA22) -> 20 | AC22: =(Z22/AB22)*100 -> 90
A23: 12 | B23: UI23EC14 | C23: CHIRAG KUMAR | D23: P | E23: A | F23: P | G23: P | H23: A | I23: A | J23: P | K23: A | L23: A | M23: P | N23: A | O23: A | P23: A | Q23: A | R23: A | S23: P | T23: P | U23: P | V23: P | W23: P | X23: P | Z23: =COUNTIF(D23:Y23,"P") + COUNTIF(D23:Y23, "1") -> 11 | AA23: =COUNTIF(D23:Y23,"A") + COUNTIF(D23:Y23,"0") -> 10 | AB23: =SUM(Z23:AA23) -> 21 | AC23: =(Z23/AB23)*100 -> 52.380952
A24: 13 | B24: UI23EC15 | C24: CHUKKA LAHITYA | D24: P | E24: P | F24: P | G24: P | H24: A | I24: A | J24: P | K24: P | L24: P | M24: P | N24: P | O24: P | P24: P | Q24: P | R24: P | S24: P | T24: P | U24: P | V24: P | W24: P | X24: P | Z24: =COUNTIF(D24:Y24,"P") + COUNTIF(D24:Y24, "1") -> 19 | AA24: =COUNTIF(D24:Y24,"A") + COUNTIF(D24:Y24,"0") -> 2 | AB24: =SUM(Z24:AA24) -> 21 | AC24: =(Z24/AB24)*100 -> 90.47619
A25: 14 | B25: UI23EC16 | C25: DEVANSH BOHARE | D25: P | E25: P | F25: P | G25: P | H25: A | I25: A | J25: P | K25: A | L25: A | M25: P | N25: P | O25: P | P25: P | Q25: P | R25: P | S25: P | T25: P | U25: P | V25: P | W25: P | X25: P | Z25: =COUNTIF(D25:Y25,"P") + COUNTIF(D25:Y25, "1") -> 17 | AA25: =COUNTIF(D25:Y25,"A") + COUNTIF(D25:Y25,"0") -> 4 | AB25: =SUM(Z25:AA25) -> 21 | AC25: =(Z25/AB25)*100 -> 80.952381
A26: 15 | B26: UI23EC17 | C26: DHANANJAY KUMAR | D26: P | E26: P | F26: P | G26: P | H26: A | I26: A | J26: P | K26: P | L26: P | M26: P | N26: P | O26: A | P26: A | Q26: A | R26: A | S26: P | T26: A | U26: P | V26: A | W26: A | X26: A | Z26: =COUNTIF(D26:Y26,"P") + COUNTIF(D26:Y26, "1") -> 11 | AA26: =COUNTIF(D26:Y26,"A") + COUNTIF(D26:Y26,"0") -> 10 | AB26: =SUM(Z26:AA26) -> 21 | AC26: =(Z26/AB26)*100 -> 52.380952
A27: 16 | B27: UI23EC18 | C27: DHARAVATH SAI DEEPIKA | D27: A | E27: P | F27: P | G27: P | H27: A | I27: A | J27: P | K27: P | L27: P | M27: P | N27: P | O27: P | P27: P | Q27: P | R27: P | S27: P | T27: P | U27: P | V27: P | W27: P | X27: P | Z27: =COUNTIF(D27:Y27,"P") + COUNTIF(D27:Y27, "1") -> 18 | AA27: =COUNTIF(D27:Y27,"A") + COUNTIF(D27:Y27,"0") -> 3 | AB27: =SUM(Z27:AA27) -> 21 | AC27: =(Z27/AB27)*100 -> 85.714286
A28: 17 | B28: UI23EC19 | C28: DANNANA DILEEP | D28: P | E28: A | F28: A | G28: P | H28: A | I28: A | J28: P | K28: P | L28: P | M28: P | N28: P | O28: P | P28: P | Q28: P | R28: P | S28: P | T28: P | U28: P | V28: P | W28: P | X28: P | Z28: =COUNTIF(D28:Y28,"P") + COUNTIF(D28:Y28, "1") -> 17 | AA28: =COUNTIF(D28:Y28,"A") + COUNTIF(D28:Y28,"0") -> 4 | AB28: =SUM(Z28:AA28) -> 21 | AC28: =(Z28/AB28)*100 -> 80.952381
A29: 18 | B29: UI23EC20 | C29: GAJJELA SINDHUJA | D29: P | E29: A | F29: A | G29: P | H29: P | I29: P | J29: P | K29: A | L29: P | M29: A | N29: P | O29: P | P29: P | Q29: A | R29: A | S29: P | T29: P | U29: P | V29: P | W29: P | X29: P | Z29: =COUNTIF(D29:Y29,"P") + COUNTIF(D29:Y29, "1") -> 15 | AA29: =COUNTIF(D29:Y29,"A") + COUNTIF(D29:Y29,"0") -> 6 | AB29: =SUM(Z29:AA29) -> 21 | AC29: =(Z29/AB29)*100 -> 71.428571
A30: 19 | B30: UI23EC21 | C30: GANESH VINOD TILEKAR | D30: A | E30: P | F30: P | G30: P | H30: P | I30: P | J30: P | K30: A | L30: P | M30: A | N30: P | O30: P | P30: P | Q30: P | R30: P | S30: A | T30: P | U30: P | V30: A | W30: A | X30: A | Z30: =COUNTIF(D30:Y30,"P") + COUNTIF(D30:Y30, "1") -> 14 | AA30: =COUNTIF(D30:Y30,"A") + COUNTIF(D30:Y30,"0") -> 7 | AB30: =SUM(Z30:AA30) -> 21 | AC30: =(Z30/AB30)*100 -> 66.666667
A31: 20 | B31: UI23EC22 | C31: GUDEPU SNUHITH | D31: P | E31: P | F31: P | G31: P | H31: A | I31: A | J31: P | K31: P | L31: P | M31: P | N31: P | O31: P | P31: P | Q31: P | R31: P | S31: P | T31: P | U31: P | V31: P | W31: P | X31: P | Z31: =COUNTIF(D31:Y31,"P") + COUNTIF(D31:Y31, "1") -> 19 | AA31: =COUNTIF(D31:Y31,"A") + COUNTIF(D31:Y31,"0") -> 2 | AB31: =SUM(Z31:AA31) -> 21 | AC31: =(Z31/AB31)*100 -> 90.47619
A32: 21 | B32: UI23EC23 | C32: HEVIN SANJAYBHAI PATEL | D32: P | E32: P | F32: P | G32: P | H32: A | I32: A | J32: P | K32: A | L32: A | M32: A | N32: P | O32: A | P32: A | Q32: A | R32: A | S32: P | T32: P | U32: P | V32: P | W32: P | X32: P | Z32: =COUNTIF(D32:Y32,"P") + COUNTIF(D32:Y32, "1") -> 12 | AA32: =COUNTIF(D32:Y32,"A") + COUNTIF(D32:Y32,"0") -> 9 | AB32: =SUM(Z32:AA32) -> 21 | AC32: =(Z32/AB32)*100 -> 57.142857
A33: 22 | B33: UI23EC24 | C33: HIMANSHU SHEKHAR | D33: A | E33: A | F33: A | G33: P | H33: A | I33: A | J33: P | K33: P | L33: P | M33: P | N33: P | O33: P | P33: P | Q33: P | R33: P | S33: P | T33: P | U33: P | V33: P | W33: P | X33: P | Z33: =COUNTIF(D33:Y33,"P") + COUNTIF(D33:Y33, "1") -> 16 | AA33: =COUNTIF(D33:Y33,"A") + COUNTIF(D33:Y33,"0") -> 5 | AB33: =SUM(Z33:AA33) -> 21 | AC33: =(Z33/AB33)*100 -> 76.190476
A34: 23 | B34: UI23EC25 | C34: HIMANSHU YADAV | D34: P | E34: P | F34: P | G34: P | H34: A | I34: A | J34: P | K34: P | L34: P | M34: P | N34: P | O34: P | P34: P | Q34: A | R34: A | S34: A | T34: P | U34: P | V34: P | W34: P | X34: P | Z34: =COUNTIF(D34:Y34,"P") + COUNTIF(D34:Y34, "1") -> 16 | AA34: =COUNTIF(D34:Y34,"A") + COUNTIF(D34:Y34,"0") -> 5 | AB34: =SUM(Z34:AA34) -> 21 | AC34: =(Z34/AB34)*100 -> 76.190476
... A53: 42 | B53: UI23EC51 | C53: RITIK KUMAR | D53: P | E53: P | F53: P | G53: A | H53: A | I53: A | J53: P | K53: P | L53: P | M53: P | N53: A | O53: P | P53: P | Q53: P | R53: P | S53: P | T53: P | U53: P | V53: P | W53: P | X53: P | Z53: =COUNTIF(D53:Y53,"P") + COUNTIF(D53:Y53, "1") -> 17 | AA53: =COUNTIF(D53:Y53,"A") + COUNTIF(D53:Y53,"0") -> 4 | AB53: =SUM(Z53:AA53) -> 21 | AC53: =(Z53/AB53)*100 -> 80.952381
A54: 43 | B54: UI23EC52 | C54: RUDRAKSH PARMAR | D54: P | E54: A | F54: A | G54: A | H54: A | I54: A | J54: A | K54: P | L54: P | M54: P | O54: A | P54: A | Q54: A | R54: A | S54: P | T54: P | U54: P | V54: A | W54: A | X54: A | Z54: =COUNTIF(D54:Y54,"P") + COUNTIF(D54:Y54, "1") -> 7 | AA54: =COUNTIF(D54:Y54,"A") + COUNTIF(D54:Y54,"0") -> 13 | AB54: =SUM(Z54:AA54) -> 20 | AC54: =(Z54/AB54)*100 -> 35
A55: 44 | B55: UI23EC55 | C55: SAMRUDDHI SHAILLENDRA RAHATE | D55: A | E55: P | F55: P | G55: P | H55: A | I55: A | J55: P | K55: A | L55: A | M55: P | N55: P | O55: P | P55: P | Q55: P | R55: P | S55: P | T55: P | U55: P | V55: P | W55: P | X55: P | Z55: =COUNTIF(D55:Y55,"P") + COUNTIF(D55:Y55, "1") -> 16 | AA55: =COUNTIF(D55:Y55,"A") + COUNTIF(D55:Y55,"0") -> 5 | AB55: =SUM(Z55:AA55) -> 21 | AC55: =(Z55/AB55)*100 -> 76.190476
A56: 46 | B56: UI23EC57 | C56: SHREYA SHARMA | D56: A | E56: P | F56: P | G56: P | H56: A | I56: A | J56: P | K56: A | L56: A | M56: P | N56: P | O56: A | P56: A | Q56: P | R56: P | S56: P | T56: P | U56: P | V56: P | W56: P | X56: P | Z56: =COUNTIF(D56:Y56,"P") + COUNTIF(D56:Y56, "1") -> 14 | AA56: =COUNTIF(D56:Y56,"A") + COUNTIF(D56:Y56,"0") -> 7 | AB56: =SUM(Z56:AA56) -> 21 | AC56: =(Z56/AB56)*100 -> 66.666667
A57: 47 | B57: UI23EC58 | C57: SIVA DHEERAJ ETHAMSETTI | D57: P | E57: P | F57: P | G57: P | H57: A | I57: A | J57: P | K57: P | L57: P | M57: P | N57: P | O57: P | P57: P | Q57: P | R57: P | S57: P | T57: A | U57: A | V57: P | W57: P | X57: P | Z57: =COUNTIF(D57:Y57,"P") + COUNTIF(D57:Y57, "1") -> 17 | AA57: =COUNTIF(D57:Y57,"A") + COUNTIF(D57:Y57,"0") -> 4 | AB57: =SUM(Z57:AA57) -> 21 | AC57: =(Z57/AB57)*100 -> 80.952381
A58: 48 | B58: UI23EC59 | C58: SPARSH SAXENA | D58: P | E58: A | F58: A | G58: P | H58: P | I58: P | J58: P | K58: A | L58: A | M58: P | N58: P | O58: P | P58: P | Q58: A | R58: A | S58: P | T58: P | U58: P | V58: P | W58: P | X58: P | Z58: =COUNTIF(D58:Y58,"P") + COUNTIF(D58:Y58, "1") -> 15 | AA58: =COUNTIF(D58:Y58,"A") + COUNTIF(D58:Y58,"0") -> 6 | AB58: =SUM(Z58:AA58) -> 21 | AC58: =(Z58/AB58)*100 -> 71.428571
A59: 49 | B59: UI23EC60 | C59: SUMANT KUMAR | D59: P | E59: P | F59: P | G59: P | H59: P | I59: P | J59: P | K59: A | L59: P | M59: A | N59: P | O59: P | P59: P | Q59: P | R59: P | S59: P | T59: A | U59: A | V59: P | W59: P | X59: P | Z59: =COUNTIF(D59:Y59,"P") + COUNTIF(D59:Y59, "1") -> 17 | AA59: =COUNTIF(D59:Y59,"A") + COUNTIF(D59:Y59,"0") -> 4 | AB59: =SUM(Z59:AA59) -> 21 | AC59: =(Z59/AB59)*100 -> 80.952381
A60: 50 | B60: UI23EC61 | C60: SURENDRA BABU KOTHAPALLI | D60: A | E60: P | F60: P | G60: P | H60: P | I60: P | J60: P | K60: A | L60: A | M60: P | N60: P | O60: P | P60: P | Q60: P | R60: P | S60: P | T60: P | U60: P | V60: P | W60: P | X60: P | Z60: =COUNTIF(D60:Y60,"P") + COUNTIF(D60:Y60, "1") -> 18 | AA60: =COUNTIF(D60:Y60,"A") + COUNTIF(D60:Y60,"0") -> 3 | AB60: =SUM(Z60:AA60) -> 21 | AC60: =(Z60/AB60)*100 -> 85.714286
A61: 51 | B61: UI23EC62 | C61: TAMANAMPUDI PHANI SAINADHA REDDY | D61: P | E61: P | F61: P | G61: P | H61: A | I61: A | J61: P | K61: P | L61: P | M61: P | N61: P | O61: P | P61: P | Q61: P | R61: P | S61: P | T61: A | U61: A | V61: P | W61: P | X61: P | Z61: =COUNTIF(D61:Y61,"P") + COUNTIF(D61:Y61, "1") -> 17 | AA61: =COUNTIF(D61:Y61,"A") + COUNTIF(D61:Y61,"0") -> 4 | AB61: =SUM(Z61:AA61) -> 21 | AC61: =(Z61/AB61)*100 -> 80.952381
...

Sheet CSE_B2
A1: Indian Institute of Information Technology (IIIT), Surat
A2: Computer Science and Engineering Department
A3: B.Tech - III Semester - V
A4: Subject Name:- Could Computing and Big data infrastructure (CS- 504)
A5: Subject Coordinator:
A6: Academic Year: 2025-2026
A7: Academic Year: 2023-2024
D9: JULY | E9: AUG | I9: SEP | M9: OCT | P9: NOV | T9: Total P | U9: Total A | V9: Total | W9: Present
D10: 31 | E10: 7 | F10: 14 | G10: 28 | I10: 4 | J10: 11 | K10: 18 | M10: 9 | N10: 16 | O10: 28 | P10: 4 | Q10: 11
A11: Sr. No | B11: Enrollment No. | C11: Name
A12: 38 | B12: UI23CS41 | C12: MEET MANOJBHAI PATEL | D12: P | E12: P | F12: P | G12: A | I12: P | J12: P | K12: P | M12: P | N12: P | O12: P | P12: P | Q12: P | T12: =COUNTIF(D12:R12,"P")+COUNTIF(D12:R12,"1") -> 11 | U12: =COUNTIF(D12:R12,"A")+COUNTIF(D12:R12,"0") -> 1 | V12: =SUM(T12:U12) -> 12 | W12: =(T12/V12)*100 -> 91.666667
A13: 39 | B13: UI23CS42 | C13: MEET PARESH PARMAR | D13: P | E13: P | F13: P | G13: A | I13: P | J13: P | K13: P | M13: A | N13: P | O13: A | P13: P | Q13: P | T13: =COUNTIF(D13:R13,"P")+COUNTIF(D13:R13,"1") -> 9 | U13: =COUNTIF(D13:R13,"A")+COUNTIF(D13:R13,"0") -> 3 | V13: =SUM(T13:U13) -> 12 | W13: =(T13/V13)*100 -> 75
A14: 40 | B14: UI23CS43 | C14: MEET SHAH | D14: A | E14: A | F14: A | G14: A | I14: A | J14: A | K14: A | M14: A | N14: A | O14: A | P14: A | Q14: A | T14: =COUNTIF(D14:R14,"P")+COUNTIF(D14:R14,"1") -> 0 | U14: =COUNTIF(D14:R14,"A")+COUNTIF(D14:R14,"0") -> 12 | V14: =SUM(T14:U14) -> 12 | W14: =(T14/V14)*100 -> 0
A15: 41 | B15: UI23CS44 | C15: MEETIKSHA | D15: P | E15: P | F15: P | G15: P | I15: P | J15: A | K15: P | M15: P | N15: A | O15: A | P15: P | Q15: P | T15: =COUNTIF(D15:R15,"P")+COUNTIF(D15:R15,"1") -> 9 | U15: =COUNTIF(D15:R15,"A")+COUNTIF(D15:R15,"0") -> 3 | V15: =SUM(T15:U15) -> 12 | W15: =(T15/V15)*100 -> 75
A16: 42 | B16: UI23CS45 | C16: MOHAMMAD SAQUIB | D16: P | E16: P | F16: P | G16: A | I16: P | J16: A | K16: P | M16: P | N16: A | O16: P | P16: P | Q16: P | T16: =COUNTIF(D16:R16,"P")+COUNTIF(D16:R16,"1") -> 9 | U16: =COUNTIF(D16:R16,"A")+COUNTIF(D16:R16,"0") -> 3 | V16: =SUM(T16:U16) -> 12 | W16: =(T16/V16)*100 -> 75
A17: 43 | B17: UI23CS46 | C17: MUDAVATH PRAVEEN NAYAK | D17: P | E17: A | F17: A | G17: P | I17: A | J17: A | K17: A | M17: A | N17: A | O17: A | P17: P | Q17: A | T17: =COUNTIF(D17:R17,"P")+COUNTIF(D17:R17,"1") -> 3 | U17: =COUNTIF(D17:R17,"A")+COUNTIF(D17:R17,"0") -> 9 | V17: =SUM(T17:U17) -> 12 | W17: =(T17/V17)*100 -> 25
A18: 44 | B18: UI23CS47 | C18: NAGANDLA SIDDHARRDHAA | D18: A | E18: P | F18: P | G18: P | I18: P | J18: P | K18: P | M18: P | N18: P | O18: P | P18: P | Q18: P | T18: =COUNTIF(D18:R18,"P")+COUNTIF(D18:R18,"1") -> 11 | U18: =COUNTIF(D18:R18,"A")+COUNTIF(D18:R18,"0") -> 1 | V18: =SUM(T18:U18) -> 12 | W18: =(T18/V18)*100 -> 91.666667
A19: 45 | B19: UI23CS48 | C19: NITISH | D19: P | E19: P | F19: A | G19: P | I19: P | J19: P | K19: P | M19: P | N19: P | O19: P | P19: A | Q19: A | T19: =COUNTIF(D19:R19,"P")+COUNTIF(D19:R19,"1") -> 9 | U19: =COUNTIF(D19:R19,"A")+COUNTIF(D19:R19,"0") -> 3 | V19: =SUM(T19:U19) -> 12 | W19: =(T19/V19)*100 -> 75
A20: 46 | B20: UI23CS49 | C20: PANKAJ KUMAR | D20: P | E20: P | F20: A | G20: P | I20: P | J20: A | K20: P | M20: P | N20: P | O20: A | P20: P | Q20: P | T20: =COUNTIF(D20:R20,"P")+COUNTIF(D20:R20,"1") -> 9 | U20: =COUNTIF(D20:R20,"A")+COUNTIF(D20:R20,"0") -> 3 | V20: =SUM(T20:U20) -> 12 | W20: =(T20/V20)*100 -> 75
A21: 47 | B21: UI23CS50 | C21: PERAM PRIYATHAM REDDY | D21: P | E21: P | F21: P | G21: P | I21: P | J21: P | K21: P | M21: P | N21: P | O21: P | P21: P | Q21: A | T21: =COUNTIF(D21:R21,"P")+COUNTIF(D21:R21,"1") -> 11 | U21: =COUNTIF(D21:R21,"A")+COUNTIF(D21:R21,"0") -> 1 | V21: =SUM(T21:U21) -> 12 | W21: =(T21/V21)*100 -> 91.666667
A22: 48 | B22: UI23CS51 | C22: PIPALIYA MOHIT SHAILESHBHAI | D22: P | E22: P | F22: P | G22: P | I22: P | J22: P | K22: A | M22: P | N22: P | O22: P | P22: P | Q22: P | T22: =COUNTIF(D22:R22,"P")+COUNTIF(D22:R22,"1") -> 11 | U22: =COUNTIF(D22:R22,"A")+COUNTIF(D22:R22,"0") -> 1 | V22: =SUM(T22:U22) -> 12 | W22: =(T22/V22)*100 -> 91.666667
A23: 49 | B23: UI23CS52 | C23: PRAMITH SAI THALLA | D23: P | E23: P | F23: P | G23: P | I23: P | J23: P | K23: P | M23: P | N23: P | O23: A | P23: P | Q23: A | T23: =COUNTIF(D23:R23,"P")+COUNTIF(D23:R23,"1") -> 10 | U23: =COUNTIF(D23:R23,"A")+COUNTIF(D23:R23,"0") -> 2 | V23: =SUM(T23:U23) -> 12 | W23: =(T23/V23)*100 -> 83.333333
... A49: 75 | B49: UI22CS42 | C49: MAKWANA KANVI | D49: P | E49: P | F49: P | G49: P | I49: P | J49: P | K49: P | M49: P | N49: P | O49: P | P49: P | Q49: P | T49: =COUNTIF(D49:R49,"P")+COUNTIF(D49:R49,"1") -> 12 | U49: =COUNTIF(D49:R49,"A")+COUNTIF(D49:R49,"0") -> 0 | V49: =SUM(T49:U49) -> 12 | W49: =(T49/V49)*100 -> 100
C54: No. of Present Student | D54: =COUNTIF(D11:D53,"P") + COUNTIF(D11:D53, "1") -> 32 | E54: =COUNTIF(E11:E53,"P") + COUNTIF(E11:E53, "1") -> 36 | F54: =COUNTIF(F11:F53,"P") + COUNTIF(F11:F53, "1") -> 30 | G54: =COUNTIF(G11:G53,"P") + COUNTIF(G11:G53, "1") -> 30 | H54: =COUNTIF(H11:H53,"P") + COUNTIF(H11:H53, "1") -> 0 | I54: =COUNTIF(I11:I53,"P") + COUNTIF(I11:I53, "1") -> 33 | J54: =COUNTIF(J11:J53,"P") + COUNTIF(J11:J53, "1") -> 25 | M54: =COUNTIF(M11:M53,"P") + COUNTIF(M11:M53, "1") -> 33 | N54: =COUNTIF(N11:N53,"P") + COUNTIF(N11:N53, "1") -> 22 | O54: =COUNTIF(O11:O53,"P") + COUNTIF(O11:O53, "1") -> 21 | P54: =COUNTIF(P11:P53,"P") + COUNTIF(P11:P53, "1") -> 35 | Q54: =COUNTIF(Q11:Q53,"P") + COUNTIF(Q11:Q53, "1") -> 27 | R54: =COUNTIF(R11:R53,"P") + COUNTIF(R11:R53, "1") -> 0 | T54: =COUNTIF(T11:T53,"P") + COUNTIF(T11:T53, "1") -> 0 | U54: =COUNTIF(U11:U53,"P") + COUNTIF(U11:U53, "1") -> 10 | V54: =COUNTIF(V11:V53,"P") + COUNTIF(V11:V53, "1") -> 0
C55: No. of Absent Student | D55: =COUNTIF(D12:D53,"A") + COUNTIF(D12:D53, "1") -> 6 | E55: =COUNTIF(E12:E53,"A") + COUNTIF(E12:E53, "1") -> 2 | F55: =COUNTIF(F12:F53,"A") + COUNTIF(F12:F53, "1") -> 8 | G55: =COUNTIF(G12:G53,"A") + COUNTIF(G12:G53, "1") -> 8 | H55: =COUNTIF(H12:H53,"A") + COUNTIF(H12:H53, "1") -> 0 | I55: =COUNTIF(I12:I53,"A") + COUNTIF(I12:I53, "1") -> 5 | J55: =COUNTIF(J12:J53,"A") + COUNTIF(J12:J53, "1") -> 13 | M55: =COUNTIF(M12:M53,"A") + COUNTIF(M12:M53, "1") -> 5 | N55: =COUNTIF(N12:N53,"A") + COUNTIF(N12:N53, "1") -> 16 | O55: =COUNTIF(O12:O53,"A") + COUNTIF(O12:O53, "1") -> 17 | P55: =COUNTIF(P12:P53,"A") + COUNTIF(P12:P53, "1") -> 3 | Q55: =COUNTIF(Q12:Q53,"A") + COUNTIF(Q12:Q53, "1") -> 11 | R55: =COUNTIF(R12:R53,"A") + COUNTIF(R12:R53, "1") -> 0 | T55: =COUNTIF(T12:T53,"A") + COUNTIF(T12:T53, "1") -> 0 | U55: =COUNTIF(U12:U53,"A") + COUNTIF(U12:U53, "1") -> 10 | V55: =COUNTIF(V12:V53,"A") + COUNTIF(V12:V53, "1") -> 0

Sheet CSE_B1
A1: Indian Institute of Information Technology (IIIT), Surat
A2: Indian Institute of Information Technology (IIIT), Surat
A3: Computer Science and Engineering Department
A4: B.Tech - III Semester - V
A5: Subject Name:- Could Computing and Big data infrastructure (CS- 504)
A6: Subject Coordinator:
A7: Academic Year: 2025-2026
D9: JULY | E9: AUGUST | I9: SEPTEMBER | K9: OCTOBER | O9: NOVEMBER | S9: Total P | T9: Total A | U9: Total | V9: Present
D10: 30 | E10: 6 | F10: 13 | G10: 22 | H10: 29 | I10: 12 | K10: 3 | L10: 10 | M10: 17 | N10: 30 | O10: 6
A11: Sr. No | B11: Enrollment No. | C11: Name
A12: 1 | B12: UI23CS01 | C12: ABHINAV | D12: A | E12: P | F12: P | G12: P | H12: P | I12: A | K12: A | L12: P | M12: A | N12: P | O12: A | S12: =COUNTIF(D12:O12,"P") + COUNTIF(D12:O12, "1") -> 6 | T12: =COUNTIF(D12:O12,"A") + COUNTIF(D12:O12,"0") -> 5 | U12: =SUM(S12:T12) -> 11 | V12: =(S12/U12)*100 -> 54.545455
A13: 2 | B13: UI23CS02 | C13: ABHISHEK YADAV | D13: P | E13: P | F13: P | G13: P | H13: P | I13: P | K13: P | L13: P | M13: A | N13: P | O13: P | S13: =COUNTIF(D13:O13,"P") + COUNTIF(D13:O13, "1") -> 10 | T13: =COUNTIF(D13:O13,"A") + COUNTIF(D13:O13,"0") -> 1 | U13: =SUM(S13:T13) -> 11 | V13: =(S13/U13)*100 -> 90.909091
A14: 3 | B14: UI23CS03 | C14: AKHILESH SINGH | D14: A | E14: A | F14: P | G14: P | H14: A | I14: P | K14: P | L14: A | M14: A | N14: P | O14: A | S14: =COUNTIF(D14:O14,"P") + COUNTIF(D14:O14, "1") -> 5 | T14: =COUNTIF(D14:O14,"A") + COUNTIF(D14:O14,"0") -> 6 | U14: =SUM(S14:T14) -> 11 | V14: =(S14/U14)*100 -> 45.454545
A15: 4 | B15: UI23CS05 | C15: AMAN DUDI | D15: P | E15: A | F15: P | G15: P | H15: P | I15: A | K15: P | L15: P | M15: A | N15: P | O15: A | S15: =COUNTIF(D15:O15,"P") + COUNTIF(D15:O15, "1") -> 7 | T15: =COUNTIF(D15:O15,"A") + COUNTIF(D15:O15,"0") -> 4 | U15: =SUM(S15:T15) -> 11 | V15: =(S15/U15)*100 -> 63.636364
A16: 5 | B16: UI23CS06 | C16: AMAN KUMAR | D16: P | E16: A | F16: P | G16: P | H16: P | I16: A | K16: P | L16: P | M16: A | N16: P | O16: P | S16: =COUNTIF(D16:O16,"P") + COUNTIF(D16:O16, "1") -> 8 | T16: =COUNTIF(D16:O16,"A") + COUNTIF(D16:O16,"0") -> 3 | U16: =SUM(S16:T16) -> 11 | V16: =(S16/U16)*100 -> 72.727273
A17: 6 | B17: UI23CS07 | C17: ANJALI | D17: A | E17: P | F17: P | G17: P | H17: P | I17: A | K17: P | L17: P | M17: A | N17: P | O17: A | S17: =COUNTIF(D17:O17,"P") + COUNTIF(D17:O17, "1") -> 7 | T17: =COUNTIF(D17:O17,"A") + COUNTIF(D17:O17,"0") -> 4 | U17: =SUM(S17:T17) -> 11 | V17: =(S17/U17)*100 -> 63.636364
A18: 7 | B18: UI23CS08 | C18: ANUBHAV RAJPUT | D18: P | E18: A | F18: P | G18: A | H18: P | I18: A | K18: A | L18: P | M18: A | N18: P | O18: A | S18: =COUNTIF(D18:O18,"P") + COUNTIF(D18:O18, "1") -> 5 | T18: =COUNTIF(D18:O18,"A") + COUNTIF(D18:O18,"0") -> 6 | U18: =SUM(S18:T18) -> 11 | V18: =(S18/U18)*100 -> 45.454545
A19: 8 | B19: UI23CS09 | C19: AVIRAL PANDEY | D19: P | E19: P | F19: P | G19: P | H19: P | I19: A | K19: P | L19: P | M19: A | N19: P | O19: A | S19: =COUNTIF(D19:O19,"P") + COUNTIF(D19:O19, "1") -> 8 | T19: =COUNTIF(D19:O19,"A") + COUNTIF(D19:O19,"0") -> 3 | U19: =SUM(S19:T19) -> 11 | V19: =(S19/U19)*100 -> 72.727273
A20: 9 | B20: UI23CS10 | C20: BAPATHI VENKATA SHV REDDY | D20: A | E20: A | F20: A | G20: P | H20: A | I20: P | K20: P | L20: P | M20: A | N20: P | O20: A | S20: =COUNTIF(D20:O20,"P") + COUNTIF(D20:O20, "1") -> 5 | T20: =COUNTIF(D20:O20,"A") + COUNTIF(D20:O20,"0") -> 6 | U20: =SUM(S20:T20) -> 11 | V20: =(S20/U20)*100 -> 45.454545
A21: 10 | B21: UI23CS11 | C21: BELLAM APOORVA | D21: P | E21: P | F21: P | G21: P | H21: P | I21: P | K21: P | L21: P | M21: A | N21: P | O21: P | S21: =COUNTIF(D21:O21,"P") + COUNTIF(D21:O21, "1") -> 10 | T21: =COUNTIF(D21:O21,"A") + COUNTIF(D21:O21,"0") -> 1 | U21: =SUM(S21:T21) -> 11 | V21: =(S21/U21)*100 -> 90.909091
A22: 11 | B22: UI23CS12 | C22: BHUKYA LINGANNA | D22: A | E22: A | F22: A | G22: A | H22: A | I22: A | K22: A | L22: A | M22: A | N22: A | O22: A | S22: =COUNTIF(D22:O22,"P") + COUNTIF(D22:O22, "1") -> 0 | T22: =COUNTIF(D22:O22,"A") + COUNTIF(D22:O22,"0") -> 11 | U22: =SUM(S22:T22) -> 11 | V22: =(S22/U22)*100 -> 0
A23: 12 | B23: UI23CS13 | C23: BHUPENDRA KUMAR | D23: P | E23: P | F23: A | G23: P | H23: P | I23: P | K23: P | L23: P | M23: A | N23: P | O23: P | S23: =COUNTIF(D23:O23,"P") + COUNTIF(D23:O23, "1") -> 9 | T23: =COUNTIF(D23:O23,"A") + COUNTIF(D23:O23,"0") -> 2 | U23: =SUM(S23:T23) -> 11 | V23: =(S23/U23)*100 -> 81.818182
... A48: 37 | B48: UI23CS40 | C48: MAYANK KUMAR SAGAR | D48: P | E48: A | F48: A | G48: P | H48: P | I48: P | K48: P | L48: P | M48: A | N48: P | O48: P | S48: =COUNTIF(D48:O48,"P") + COUNTIF(D48:O48, "1") -> 8 | T48: =COUNTIF(D48:O48,"A") + COUNTIF(D48:O48,"0") -> 3 | U48: =SUM(S48:T48) -> 11 | V48: =(S48/U48)*100 -> 72.727273
C52: No. of Present Student | D52: =COUNTIF(D12:D51,"P") + COUNTIF(D12:D51, "1") -> 29 | E52: =COUNTIF(E12:E51,"P") + COUNTIF(E12:E51, "1") -> 25 | F52: =COUNTIF(F12:F51,"P") + COUNTIF(F12:F51, "1") -> 30 | G52: =COUNTIF(G12:G51,"P") + COUNTIF(G12:G51, "1") -> 34 | H52: =COUNTIF(H12:H51,"P") + COUNTIF(H12:H51, "1") -> 29 | I52: =COUNTIF(I12:I51,"P") + COUNTIF(I12:I51, "1") -> 22 | J52: =COUNTIF(J12:J51,"P") + COUNTIF(J12:J51, "1") -> 0 | K52: =COUNTIF(K12:K51,"P") + COUNTIF(K12:K51, "1") -> 30 | ... O52: =COUNTIF(O12:O51,"P") + COUNTIF(O12:O51, "1") -> 19
C53: No. of Absent Student | D53: =COUNTIF(D13:D51,"A") + COUNTIF(D13:D51, "1") -> 7 | E53: =COUNTIF(E13:E51,"A") + COUNTIF(E13:E51, "1") -> 12 | F53: =COUNTIF(F13:F51,"A") + COUNTIF(F13:F51, "1") -> 7 | G53: =COUNTIF(G13:G51,"A") + COUNTIF(G13:G51, "1") -> 3 | H53: =COUNTIF(H13:H51,"A") + COUNTIF(H13:H51, "1") -> 8 | I53: =COUNTIF(I13:I51,"A") + COUNTIF(I13:I51, "1") -> 14 | J53: =COUNTIF(J13:J51,"A") + COUNTIF(J13:J51, "1") -> 0 | K53: =COUNTIF(K13:K51,"A") + COUNTIF(K13:K51, "1") -> 6 | ... O53: =COUNTIF(O13:O51,"A") + COUNTIF(O13:O51, "1") -> 17

Sheet ECE_B2
A1: Indian Institute of Information Technology (IIIT), Surat
A2: Computer Science and Engineering Department
A3: B.Tech - III Semester - V
A4: Subject Name:- Could Computing and Big data infrastructure (CS- 504)
A5: Subject Coordinator:
A6: Academic Year: 2025-2026
D8: August | H8: September | L8: OCT | Q8: NOV | W8: Total P | X8: Total A | Y8: Total | Z8: Present
D9: 1 | E9: 8 | F9: 30 | H9: 1 | I9: 8 | J9: 15 | L9: 27 | M9: 45727 | N9: 4 | Q9: 10
A10: Sr. No | B10: Enrollment No. | C10: Students Name
A11: 31 | B11: UI23EC36 | C11: MANOJ KUMAWAT | D11: P | E11: P | F11: P | H11: P | I11: P | J11: P | L11: P | M11: P | Q11: P | W11: =COUNTIF(D11:V11,"P")+COUNTIF(D11:V11,"1") -> 8 | X11: =COUNTIF(D11:V11,"A")+COUNTIF(D11:V11,"0") -> 0 | Y11: =SUM(W11:X11) -> 8 | Z11: =(W11/Y11)*100 -> 100
A12: 32 | B12: UI23EC37 | C12: MITULKUMAR MAGANBHAI HADIYA | D12: P | E12: P | F12: P | H12: P | I12: P | J12: P | L12: A | M12: P | Q12: P | W12: =COUNTIF(D12:V12,"P")+COUNTIF(D12:V12,"1") -> 8 | X12: =COUNTIF(D12:V12,"A")+COUNTIF(D12:V12,"0") -> 1 | Y12: =SUM(W12:X12) -> 9 | Z12: =(W12/Y12)*100 -> 88.888889
A13: 33 | B13: UI23EC40 | C13: NITIN | D13: P | E13: P | F13: P | H13: P | I13: P | J13: P | L13: A | M13: P | Q13: P | W13: =COUNTIF(D13:V13,"P")+COUNTIF(D13:V13,"1") -> 8 | X13: =COUNTIF(D13:V13,"A")+COUNTIF(D13:V13,"0") -> 1 | Y13: =SUM(W13:X13) -> 9 | Z13: =(W13/Y13)*100 -> 88.888889
A14: 34 | B14: UI23EC41 | C14: OM SETH | D14: A | E14: P | F14: P | H14: P | I14: P | J14: P | L14: A | M14: P | Q14: P | W14: =COUNTIF(D14:V14,"P")+COUNTIF(D14:V14,"1") -> 7 | X14: =COUNTIF(D14:V14,"A")+COUNTIF(D14:V14,"0") -> 2 | Y14: =SUM(W14:X14) -> 9 | Z14: =(W14/Y14)*100 -> 77.777778
A15: 35 | B15: UI23EC42 | C15: PACHURU SUNIL | D15: P | E15: P | F15: P | H15: P | I15: P | J15: P | L15: A | M15: A | Q15: P | W15: =COUNTIF(D15:V15,"P")+COUNTIF(D15:V15,"1") -> 7 | X15: =COUNTIF(D15:V15,"A")+COUNTIF(D15:V15,"0") -> 2 | Y15: =SUM(W15:X15) -> 9 | Z15: =(W15/Y15)*100 -> 77.777778
A16: 36 | B16: UI23EC43 | C16: PALAK DWIVEDI | D16: A | E16: P | F16: P | H16: P | I16: P | J16: P | L16: A | M16: P | Q16: P | W16: =COUNTIF(D16:V16,"P")+COUNTIF(D16:V16,"1") -> 7 | X16: =COUNTIF(D16:V16,"A")+COUNTIF(D16:V16,"0") -> 2 | Y16: =SUM(W16:X16) -> 9 | Z16: =(W16/Y16)*100 -> 77.777778
A17: 37 | B17: UI23EC44 | C17: PRATEEK SINGH | D17: A | E17: P | F17: P | H17: P | I17: P | J17: P | L17: A | M17: P | Q17: P | W17: =COUNTIF(D17:V17,"P")+COUNTIF(D17:V17,"1") -> 7 | X17: =COUNTIF(D17:V17,"A")+COUNTIF(D17:V17,"0") -> 2 | Y17: =SUM(W17:X17) -> 9 | Z17: =(W17/Y17)*100 -> 77.777778
A18: 38 | B18: UI23EC45 | C18: PREET KUMAR | D18: P | E18: P | F18: P | H18: P | I18: P | J18: A | L18: A | M18: P | Q18: P | W18: =COUNTIF(D18:V18,"P")+COUNTIF(D18:V18,"1") -> 7 | X18: =COUNTIF(D18:V18,"A")+COUNTIF(D18:V18,"0") -> 2 | Y18: =SUM(W18:X18) -> 9 | Z18: =(W18/Y18)*100 -> 77.777778
A19: 39 | B19: UI23EC46 | C19: PRIYANSH CHOUDHARY | D19: A | E19: P | F19: P | H19: P | I19: P | J19: P | L19: A | M19: P | Q19: P | W19: =COUNTIF(D19:V19,"P")+COUNTIF(D19:V19,"1") -> 7 | X19: =COUNTIF(D19:V19,"A")+COUNTIF(D19:V19,"0") -> 2 | Y19: =SUM(W19:X19) -> 9 | Z19: =(W19/Y19)*100 -> 77.777778
A20: 40 | B20: UI23EC48 | C20: RAJAT JAIN | D20: P | E20: A | F20: P | H20: P | I20: P | J20: P | L20: A | M20: P | Q20: P | W20: =COUNTIF(D20:V20,"P")+COUNTIF(D20:V20,"1") -> 7 | X20: =COUNTIF(D20:V20,"A")+COUNTIF(D20:V20,"0") -> 2 | Y20: =SUM(W20:X20) -> 9 | Z20: =(W20/Y20)*100 -> 77.777778
A21: 41 | B21: UI23EC50 | C21: RAVI | D21: P | E21: P | F21: P | H21: P | I21: P | J21: P | L21: A | M21: P | Q21: P | W21: =COUNTIF(D21:V21,"P")+COUNTIF(D21:V21,"1") -> 8 | X21: =COUNTIF(D21:V21,"A")+COUNTIF(D21:V21,"0") -> 1 | Y21: =SUM(W21:X21) -> 9 | Z21: =(W21/Y21)*100 -> 88.888889
A22: 42 | B22: UI23EC51 | C22: RITIK KUMAR | D22: P | E22: P | F22: P | H22: P | I22: P | J22: P | L22: P | M22: P | Q22: P | W22: =COUNTIF(D22:V22,"P")+COUNTIF(D22:V22,"1") -> 9 | X22: =COUNTIF(D22:V22,"A")+COUNTIF(D22:V22,"0") -> 0 | Y22: =SUM(W22:X22) -> 9 | Z22: =(W22/Y22)*100 -> 100
... A38: 60 | B38: UI22EC35 | C38: JARAPILA CHARUSHMA | D38: A | E38: A | F38: P | H38: P | I38: P | J38: P | L38: A | M38: P | Q38: P | W38: =COUNTIF(D38:V38,"P")+COUNTIF(D38:V38,"1") -> 6 | X38: =COUNTIF(D38:V38,"A")+COUNTIF(D38:V38,"0") -> 3 | Y38: =SUM(W38:X38) -> 9 | Z38: =(W38/Y38)*100 -> 66.666667
A39: 61 | B39: UI22EC05 | C39: AAKULA PREETHI | D39: A | E39: A | F39: P | H39: P | I39: P | J39: P | L39: A | M39: P | Q39: P
C43: No. of Present Student | D43: =COUNTIF(D11:D39,"P") + COUNTIF(D11:D39, "1") -> 19 | E43: =COUNTIF(E11:E39,"P") + COUNTIF(E11:E39, "1") -> 24 | F43: =COUNTIF(F11:F39,"P") + COUNTIF(F11:F39, "1") -> 27 | G43: =COUNTIF(G11:G39,"P") + COUNTIF(G11:G39, "1") -> 0 | H43: =COUNTIF(H11:H39,"P") + COUNTIF(H11:H39, "1") -> 28 | I43: =COUNTIF(I11:I39,"P") + COUNTIF(I11:I39, "1") -> 25 | J43: =COUNTIF(J11:J39,"P") + COUNTIF(J11:J39, "1") -> 25 | K43: =COUNTIF(K11:K39,"P") + COUNTIF(K11:K39, "1") -> 0 | ... V43: =COUNTIF(V11:V39,"P") + COUNTIF(V11:V39, "1") -> 0 | W43: =COUNTIF(W10:W42,"P") + COUNTIF(W10:W42, "1") -> 0 | X43: =COUNTIF(X10:X42,"P") + COUNTIF(X10:X42, "1") -> 12 | Y43: =COUNTIF(Y10:Y42,"P") + COUNTIF(Y10:Y42, "1") -> 0
C44: No. of Absent Student | D44: =COUNTIF(D11:D39,"A") + COUNTIF(D11:D39, "1") -> 10 | E44: =COUNTIF(E11:E39,"A") + COUNTIF(E11:E39, "1") -> 5 | F44: =COUNTIF(F11:F39,"A") + COUNTIF(F11:F39, "1") -> 1 | G44: =COUNTIF(G11:G39,"A") + COUNTIF(G11:G39, "1") -> 0 | H44: =COUNTIF(H11:H39,"A") + COUNTIF(H11:H39, "1") -> 1 | I44: =COUNTIF(I11:I39,"A") + COUNTIF(I11:I39, "1") -> 4 | J44: =COUNTIF(J11:J39,"A") + COUNTIF(J11:J39, "1") -> 4 | K44: =COUNTIF(K11:K39,"A") + COUNTIF(K11:K39, "1") -> 0 | ... V44: =COUNTIF(V11:V39,"A") + COUNTIF(V11:V39, "1") -> 0 | W44: =COUNTIF(W12:W42,"A") + COUNTIF(W12:W42, "1") -> 0 | X44: =COUNTIF(X12:X42,"A") + COUNTIF(X12:X42, "1") -> 12 | Y44: =COUNTIF(Y12:Y42,"A") + COUNTIF(Y12:Y42, "1") -> 0
C46: No. of Present Students | D46: =COUNTIF(D12:D38,"P") + COUNTIF(D12:D38, "1") -> 18 | E46: =COUNTIF(E12:E38,"P") + COUNTIF(E12:E38, "1") -> 23 | F46: =COUNTIF(F12:F38,"P") + COUNTIF(F12:F38, "1") -> 26 | G46: =COUNTIF(G12:G38,"P") + COUNTIF(G12:G38, "1") -> 0 | H46: =COUNTIF(H12:H39,"P") + COUNTIF(H12:H39, "1") -> 27 | I46: =COUNTIF(I12:I38,"P") + COUNTIF(I12:I38, "1") -> 23 | J46: =COUNTIF(J12:J38,"P") + COUNTIF(J12:J38, "1") -> 23 | M46: =COUNTIF(M12:M38,"P") + COUNTIF(M12:M38, "1") -> 24 | N46: =COUNTIF(N12:N38,"P") + COUNTIF(N12:N38, "1") -> 0 | O46: =COUNTIF(O12:O38,"P") + COUNTIF(O12:O38, "1") -> 0 | P46: =COUNTIF(P12:P38,"P") + COUNTIF(P12:P38, "1") -> 0 | Q46: =COUNTIF(Q12:Q38,"P") + COUNTIF(Q12:Q38, "1") -> 23 | R46: =COUNTIF(R12:R38,"P") + COUNTIF(R12:R38, "1") -> 0 | S46: =COUNTIF(S12:S38,"P") + COUNTIF(S12:S38, "1") -> 0 | T46: =COUNTIF(T12:T38,"P") + COUNTIF(T12:T38, "1") -> 0 | ... V46: =COUNTIF(V12:V38,"P") + COUNTIF(V12:V38, "1") -> 0
C47: No. of Absent Students | D47: =COUNTIF(D12:D38,"A") + COUNTIF(D12:D38, "0") -> 9 | E47: =COUNTIF(E12:E38,"A") + COUNTIF(E12:E38, "0") -> 4 | F47: =COUNTIF(F12:F38,"A") + COUNTIF(F12:F38, "0") -> 1 | G47: =COUNTIF(G12:G38,"A") + COUNTIF(G12:G38, "0") -> 0 | H47: =COUNTIF(H12:H39,"A") + COUNTIF(H12:H39, "0") -> 1 | I47: =COUNTIF(I12:I38,"A") + COUNTIF(I12:I38, "0") -> 4 | J47: =COUNTIF(J12:J38,"A") + COUNTIF(J12:J38, "0") -> 4 | M47: =COUNTIF(M12:M38,"A") + COUNTIF(M12:M38, "0") -> 3 | N47: =COUNTIF(N12:N38,"A") + COUNTIF(N12:N38, "0") -> 0 | O47: =COUNTIF(O12:O38,"A") + COUNTIF(O12:O38, "0") -> 0 | P47: =COUNTIF(P12:P38,"A") + COUNTIF(P12:P38, "0") -> 0 | Q47: =COUNTIF(Q12:Q38,"A") + COUNTIF(Q12:Q38, "0") -> 4 | R47: =COUNTIF(R12:R38,"A") + COUNTIF(R12:R38, "0") -> 0 | S47: =COUNTIF(S12:S38,"A") + COUNTIF(S12:S38, "0") -> 0 | T47: =COUNTIF(T12:T38,"A") + COUNTIF(T12:T38, "0") -> 0 | ... V47: =COUNTIF(V12:V38,"A") + COUNTIF(V12:V38, "0") -> 0

Sheet ECE_B1
A1: Indian Institute of Information Technology (IIIT), Surat
A2: Computer Science and Engineering Department
A3: B.Tech - III Semester - V
A4: Subject Name:- Could Computing and Big data infrastructure (CS- 504)
A5: Subject Coordinator:
A6: Academic Year: 2025-2026
D8: August | I8: Sept | L8: Oct | P8: NOV | V8: Total P | W8: Total A | X8: Total | Y8: Present
D9: 4 | E9: 11 | F9: 18 | G9: 20 | I9: 3 | J9: 10 | K9: 17 | L9: 15 | M9: 8 | N9: 29 | P9: 12
A10: Sr. No | B10: Enrollment No. | C10: Name
A11: 1 | B11: UI23EC01 | C11: ABHAY JAISWAL | D11: P | E11: P | F11: P | G11: A | I11: A | J11: P | K11: A | L11: P | M11: P | N11: A | P11: P | V11: =COUNTIF(D11:U11,"P") + COUNTIF(D11:U11, "1") -> 7 | W11: =COUNTIF(D11:U11,"A") + COUNTIF(D11:U11,"0") -> 4 | X11: =SUM(V11:W11) -> 11 | Y11: =(V11/X11)*100 -> 63.636364
A12: 2 | B12: UI23EC02 | C12: ADARSH PANDEY | D12: P | E12: P | F12: P | G12: P | I12: A | J12: P | K12: A | L12: P | M12: A | N12: A | P12: P | V12: =COUNTIF(D12:U12,"P") + COUNTIF(D12:U12, "1") -> 7 | W12: =COUNTIF(D12:U12,"A") + COUNTIF(D12:U12,"0") -> 4 | X12: =SUM(V12:W12) -> 11 | Y12: =(V12/X12)*100 -> 63.636364
A13: 3 | B13: UI23EC03 | C13: ADITYA ANAND | D13: P | E13: P | F13: P | G13: P | I13: P | J13: P | K13: P | L13: P | M13: P | N13: P | P13: P | V13: =COUNTIF(D13:U13,"P") + COUNTIF(D13:U13, "1") -> 11 | W13: =COUNTIF(D13:U13,"A") + COUNTIF(D13:U13,"0") -> 0 | X13: =SUM(V13:W13) -> 11 | Y13: =(V13/X13)*100 -> 100
A14: 4 | B14: UI23EC04 | C14: ANKIT KUMAR | D14: P | E14: P | F14: P | G14: P | I14: A | J14: P | K14: P | L14: P | M14: P | N14: P | P14: P | V14: =COUNTIF(D14:U14,"P") + COUNTIF(D14:U14, "1") -> 10 | W14: =COUNTIF(D14:U14,"A") + COUNTIF(D14:U14,"0") -> 1 | X14: =SUM(V14:W14) -> 11 | Y14: =(V14/X14)*100 -> 90.909091
A15: 5 | B15: UI23EC06 | C15: ARPIT CHAUHAN | D15: P | E15: P | F15: P | G15: P | I15: P | J15: P | K15: P | L15: P | M15: P | N15: P | P15: P | V15: =COUNTIF(D15:U15,"P") + COUNTIF(D15:U15, "1") -> 11 | W15: =COUNTIF(D15:U15,"A") + COUNTIF(D15:U15,"0") -> 0 | X15: =SUM(V15:W15) -> 11 | Y15: =(V15/X15)*100 -> 100
A16: 6 | B16: UI23EC07 | C16: ARPIT KHARE | D16: A | E16: P | F16: A | G16: P | I16: P | J16: P | K16: P | L16: A | M16: P | N16: P | P16: A | V16: =COUNTIF(D16:U16,"P") + COUNTIF(D16:U16, "1") -> 7 | W16: =COUNTIF(D16:U16,"A") + COUNTIF(D16:U16,"0") -> 4 | X16: =SUM(V16:W16) -> 11 | Y16: =(V16/X16)*100 -> 63.636364
A17: 7 | B17: UI23EC08 | C17: ARYAN KUMAR | D17: P | E17: A | F17: A | G17: P | I17: P | J17: P | K17: P | L17: A | M17: P | N17: A | P17: P | V17: =COUNTIF(D17:U17,"P") + COUNTIF(D17:U17, "1") -> 7 | W17: =COUNTIF(D17:U17,"A") + COUNTIF(D17:U17,"0") -> 4 | X17: =SUM(V17:W17) -> 11 | Y17: =(V17/X17)*100 -> 63.636364
A18: 8 | B18: UI23EC09 | C18: ARYAN TIWARI | D18: P | E18: P | F18: P | G18: P | I18: P | J18: P | K18: P | L18: P | M18: P | N18: A | P18: P | V18: =COUNTIF(D18:U18,"P") + COUNTIF(D18:U18, "1") -> 10 | W18: =COUNTIF(D18:U18,"A") + COUNTIF(D18:U18,"0") -> 1 | X18: =SUM(V18:W18) -> 11 | Y18: =(V18/X18)*100 -> 90.909091
A19: 9 | B19: UI23EC11 | C19: AYUSH SINGH | D19: P | E19: A | F19: P | G19: P | I19: P | J19: P | K19: A | L19: P | M19: P | N19: P | P19: A | V19: =COUNTIF(D19:U19,"P") + COUNTIF(D19:U19, "1") -> 8 | W19: =COUNTIF(D19:U19,"A") + COUNTIF(D19:U19,"0") -> 3 | X19: =SUM(V19:W19) -> 11 | Y19: =(V19/X19)*100 -> 72.727273
A20: 10 | B20: UI23EC12 | C20: BODDU SRINIVASA RAO | D20: P | E20: P | F20: P | G20: A | I20: P | J20: P | K20: P | L20: A | M20: P | N20: A | P20: P | V20: =COUNTIF(D20:U20,"P") + COUNTIF(D20:U20, "1") -> 8 | W20: =COUNTIF(D20:U20,"A") + COUNTIF(D20:U20,"0") -> 3 | X20: =SUM(V20:W20) -> 11 | Y20: =(V20/X20)*100 -> 72.727273
A21: 11 | B21: UI23EC13 | C21: CHETHAN SAI BILLA | D21: P | E21: P | F21: P | G21: A | I21: P | J21: P | K21: A | L21: A | M21: P | N21: A | P21: P | V21: =COUNTIF(D21:U21,"P") + COUNTIF(D21:U21, "1") -> 7 | W21: =COUNTIF(D21:U21,"A") + COUNTIF(D21:U21,"0") -> 4 | X21: =SUM(V21:W21) -> 11 | Y21: =(V21/X21)*100 -> 63.636364
A22: 12 | B22: UI23EC14 | C22: CHIRAG KUMAR | D22: P | E22: P | F22: A | G22: P | I22: P | J22: P | K22: P | L22: A | M22: A | N22: A | P22: P | V22: =COUNTIF(D22:U22,"P") + COUNTIF(D22:U22, "1") -> 7 | W22: =COUNTIF(D22:U22,"A") + COUNTIF(D22:U22,"0") -> 4 | X22: =SUM(V22:W22) -> 11 | Y22: =(V22/X22)*100 -> 63.636364
... A39: 29 | B39: UI23EC34 | C39: KUNAL MAHENDRA | D39: P | E39: P | F39: A | G39: A | I39: A | J39: P | K39: A | L39: P | M39: P | N39: A | P39: P | V39: =COUNTIF(D39:U39,"P") + COUNTIF(D39:U39, "1") -> 6 | W39: =COUNTIF(D39:U39,"A") + COUNTIF(D39:U39,"0") -> 5 | X39: =SUM(V39:W39) -> 11 | Y39: =(V39/X39)*100 -> 54.545455
A40: 30 | B40: UI23EC35 | C40: MANASVI CHOUDHARY | D40: A | E40: A | F40: P | G40: P | I40: P | J40: P | K40: P | M40: P | N40: P | P40: P | V40: =COUNTIF(D40:U40,"P") + COUNTIF(D40:U40, "1") -> 8 | W40: =COUNTIF(D40:U40,"A") + COUNTIF(D40:U40,"0") -> 2 | X40: =SUM(V40:W40) -> 10 | Y40: =(V40/X40)*100 -> 80
C45: No. of Present Student | D45: =COUNTIF(D10:D40,"P") + COUNTIF(D10:D40, "1") -> 25 | E45: =COUNTIF(E10:E40,"P") + COUNTIF(E10:E40, "1") -> 24 | G45: =COUNTIF(G10:G40,"P") + COUNTIF(G10:G40, "1") -> 23 | H45: =COUNTIF(H10:H40,"P") + COUNTIF(H10:H40, "1") -> 0 | I45: =COUNTIF(I10:I40,"P") + COUNTIF(I10:I40, "1") -> 23 | J45: =COUNTIF(J10:J40,"P") + COUNTIF(J10:J40, "1") -> 29 | K45: =COUNTIF(K10:K40,"P") + COUNTIF(K10:K40, "1") -> 23 | L45: =COUNTIF(L10:L40,"P") + COUNTIF(L10:L40, "1") -> 19 | M45: =COUNTIF(M10:M40,"P") + COUNTIF(M10:M40, "1") -> 23 | P45: =COUNTIF(P10:P40,"P") + COUNTIF(P10:P40, "1") -> 25 | Q45: =COUNTIF(Q10:Q40,"P") + COUNTIF(Q10:Q40, "1") -> 0 | R45: =COUNTIF(R10:R40,"P") + COUNTIF(R10:R40, "1") -> 0 | S45: =COUNTIF(S11:S41,"P") + COUNTIF(S11:S41, "1") -> 0 | T45: =COUNTIF(T11:T41,"P") + COUNTIF(T11:T41, "1") -> 0 | U45: =COUNTIF(U11:U41,"P") + COUNTIF(U11:U41, "1") -> 0
C46: No. of Absent Student | D46: =COUNTIF(D10:D40,"A") + COUNTIF(D10:D40, "1") -> 5 | E46: =COUNTIF(E10:E40,"A") + COUNTIF(E10:E40, "1") -> 6 | G46: =COUNTIF(G10:G40,"A") + COUNTIF(G10:G40, "1") -> 7 | H46: =COUNTIF(H10:H40,"A") + COUNTIF(H10:H40, "1") -> 0 | I46: =COUNTIF(I10:I40,"A") + COUNTIF(I10:I40, "1") -> 7 | J46: =COUNTIF(J10:J40,"A") + COUNTIF(J10:J40, "1") -> 1 | K46: =COUNTIF(K10:K40,"A") + COUNTIF(K10:K40, "1") -> 7 | L46: =COUNTIF(L10:L40,"A") + COUNTIF(L10:L40, "1") -> 10 | M46: =COUNTIF(M10:M40,"A") + COUNTIF(M10:M40, "1") -> 7 | P46: =COUNTIF(P10:P40,"A") + COUNTIF(P10:P40, "1") -> 5 | Q46: =COUNTIF(Q10:Q40,"A") + COUNTIF(Q10:Q40, "1") -> 0 | R46: =COUNTIF(R10:R40,"A") + COUNTIF(R10:R40, "1") -> 0 | S46: =COUNTIF(S11:S41,"A") + COUNTIF(S11:S41, "1") -> 0 | T46: =COUNTIF(T11:T41,"A") + COUNTIF(T11:T41, "1") -> 0 | U46: =COUNTIF(U11:U41,"A") + COUNTIF(U11:U41, "1") -> 0

Sheet Total_CSE
A1: Indian Institute of Information Technology (IIIT), Surat
A2: Computer Science and Engineering Department
A3: B.Tech - III Semester - V
A4: Subject Name:- Could Computing and Big data infrastructure (CS- 504)
A5: Subject Coordinator:
A6: Academic Year: 2025-2026
D9: Present Percentage Theory (%) | E9: Present Percentage Lab (%) | F9: Present Percentage (%)
A12: Sr. No | B12: Enrollment No. | C12: Name
A13: 1 | B13: UI23CS01 | C13: ABHINAV | D13: =Th_CSE!AF11 -> 63.636364 | E13: =CSE_B1!V12 -> 54.545455 | F13: =AVERAGE(D13:E13) -> 59.090909
A14: 2 | B14: UI23CS02 | C14: ABHISHEK YADAV | D14: =Th_CSE!AF12 -> 90.909091 | E14: =CSE_B1!V13 -> 90.909091 | F14: =AVERAGE(D14:E14) -> 90.909091
A15: 3 | B15: UI23CS03 | C15: AKHILESH SINGH | D15: =Th_CSE!AF13 -> 45.454545 | E15: =CSE_B1!V14 -> 45.454545 | F15: =AVERAGE(D15:E15) -> 45.454545
A16: 4 | B16: UI23CS05 | C16: AMAN DUDI | D16: =Th_CSE!AF14 -> 86.363636 | E16: =CSE_B1!V15 -> 63.636364 | F16: =AVERAGE(D16:E16) -> 75
A17: 5 | B17: UI23CS06 | C17: AMAN KUMAR | D17: =Th_CSE!AF15 -> 63.636364 | E17: =CSE_B1!V16 -> 72.727273 | F17: =AVERAGE(D17:E17) -> 68.181818
A18: 6 | B18: UI23CS07 | C18: ANJALI | D18: =Th_CSE!AF16 -> 86.363636 | E18: =CSE_B1!V17 -> 63.636364 | F18: =AVERAGE(D18:E18) -> 75
A19: 7 | B19: UI23CS08 | C19: ANUBHAV RAJPUT | D19: =Th_CSE!AF17 -> 77.272727 | E19: =CSE_B1!V18 -> 45.454545 | F19: =AVERAGE(D19:E19) -> 61.363636
A20: 8 | B20: UI23CS09 | C20: AVIRAL PANDEY | D20: =Th_CSE!AF18 -> 90.909091 | E20: =CSE_B1!V19 -> 72.727273 | F20: =AVERAGE(D20:E20) -> 81.818182
A21: 9 | B21: UI23CS10 | C21: BAPATHI VENKATA SHV REDDY | D21: =Th_CSE!AF19 -> 63.636364 | E21: =CSE_B1!V20 -> 45.454545 | F21: =AVERAGE(D21:E21) -> 54.545455
A22: 10 | B22: UI23CS11 | C22: BELLAM APOORVA | D22: =Th_CSE!AF20 -> 90.909091 | E22: =CSE_B1!V21 -> 90.909091 | F22: =AVERAGE(D22:E22) -> 90.909091
A23: 11 | B23: UI23CS12 | C23: BHUKYA LINGANNA | D23: =Th_CSE!AF21 -> 81.818182 | E23: =CSE_B1!V22 -> 0 | F23: =AVERAGE(D23:E23) -> 40.909091
A24: 12 | B24: UI23CS13 | C24: BHUPENDRA KUMAR | D24: =Th_CSE!AF22 -> 90.909091 | E24: =CSE_B1!V23 -> 81.818182 | F24: =AVERAGE(D24:E24) -> 86.363636
... A49: 37 | B49: UI23CS40 | C49: MAYANK KUMAR SAGAR | D49: =Th_CSE!AF47 -> 90.909091 | E49: =CSE_B1!V48 -> 72.727273 | F49: =AVERAGE(D49:E49) -> 81.818182
A50: 38 | B50: UI23CS41 | C50: MEET MANOJBHAI PATEL | D50: =Th_CSE!AF49 -> 77.272727 | E50: =CSE_B2!W12 -> 91.666667 | F50: =AVERAGE(D50:E50) -> 84.469697
A51: 39 | B51: UI23CS42 | C51: MEET PARESH PARMAR | D51: =Th_CSE!AF50 -> 63.636364 | E51: =CSE_B2!W13 -> 75 | F51: =AVERAGE(D51:E51) -> 69.318182
A52: 40 | B52: UI23CS43 | C52: MEET SHAH | D52: =Th_CSE!AF51 -> 86.363636 | E52: =CSE_B2!W14 -> 0 | F52: =AVERAGE(D52:E52) -> 43.181818
A53: 41 | B53: UI23CS44 | C53: MEETIKSHA | D53: =Th_CSE!AF52 -> 77.272727 | E53: =CSE_B2!W15 -> 75 | F53: =AVERAGE(D53:E53) -> 76.136364
A54: 42 | B54: UI23CS45 | C54: MOHAMMAD SAQUIB | D54: =Th_CSE!AF53 -> 77.272727 | E54: =CSE_B2!W16 -> 75 | F54: =AVERAGE(D54:E54) -> 76.136364
A55: 43 | B55: UI23CS46 | C55: MUDAVATH PRAVEEN NAYAK | D55: =Th_CSE!AF54 -> 81.818182 | E55: =CSE_B2!W17 -> 25 | F55: =AVERAGE(D55:E55) -> 53.409091
A56: 44 | B56: UI23CS47 | C56: NAGANDLA SIDDHARRDHAA | D56: =Th_CSE!AF55 -> 86.363636 | E56: =CSE_B2!W18 -> 91.666667 | F56: =AVERAGE(D56:E56) -> 89.015152
A57: 45 | B57: UI23CS48 | C57: NITISH | D57: =Th_CSE!AF56 -> 63.636364 | E57: =CSE_B2!W19 -> 75 | F57: =AVERAGE(D57:E57) -> 69.318182
A58: 46 | B58: UI23CS49 | C58: PANKAJ KUMAR | D58: =Th_CSE!AF57 -> 63.636364 | E58: =CSE_B2!W20 -> 75 | F58: =AVERAGE(D58:E58) -> 69.318182
A59: 47 | B59: UI23CS50 | C59: PERAM PRIYATHAM REDDY | D59: =Th_CSE!AF58 -> 100 | E59: =CSE_B2!W21 -> 91.666667 | F59: =AVERAGE(D59:E59) -> 95.833333
A60: 48 | B60: UI23CS51 | C60: PIPALIYA MOHIT SHAILESHBHAI | D60: =Th_CSE!AF59 -> 68.181818 | E60: =CSE_B2!W22 -> 91.666667 | F60: =AVERAGE(D60:E60) -> 79.924242
A61: 49 | B61: UI23CS52 | C61: PRAMITH SAI THALLA | D61: =Th_CSE!AF60 -> 81.818182 | E61: =CSE_B2!W23 -> 83.333333 | F61: =AVERAGE(D61:E61) -> 82.575758
... A85: 73 | B85: UI23CS78 | C85: YUG PATEL | D85: =Th_CSE!AF84 -> 100 | E85: =CSE_B2!W47 -> 91.666667 | F85: =AVERAGE(D85:E85) -> 95.833333
A86: 74 | B86: UI22CS11 | C86: BANOTH VENKATESH | D86: =Th_CSE!AF85 | E86: =CSE_B1!V86
A87: 75 | D87: =Th_CSE!AF86 | E87: =CSE_B1!V87
A88: 76 | D88: =Th_CSE!AF87 | E88: =CSE_B1!V88
A89: 77 | D89: =Th_CSE!AF88 | E89: =CSE_B1!V89
A90: 78 | D90: =Th_CSE!AF89 | E90: =CSE_B1!V90
A91: 79 | D91: =Th_CSE!AF90 | E91: =CSE_B1!V91
...

Sheet Total_ECE
A1: Indian Institute of Information Technology (IIIT), Surat
A2: Computer Science and Engineering Department
A3: B.Tech - III Semester - V
A4: Subject Name:- Could Computing and Big data infrastructure (CS- 504)
A5: Subject Coordinator:
A6: Academic Year: 2025-2026
D9: Present Percentage Theory (%) | E9: Present Percentage Lab (%) | F9: Present Percentage (%)
A12: Sr. No | B12: Enrollment No. | C12: Name | D12: =Th_ECE!AC12 -> 71.428571 | E12: =ECE_B1!Y11 -> 63.636364 | F12: =AVERAGE(D12:E12) -> 67.532468
A13: 1 | B13: UI23EC01 | C13: ABHAY JAISWAL | D13: =Th_ECE!AC13 -> 76.190476 | E13: =ECE_B1!Y12 -> 63.636364 | F13: =AVERAGE(D13:E13) -> 69.91342
A14: 2 | B14: UI23EC02 | C14: ADARSH PANDEY | D14: =Th_ECE!AC14 -> 90.47619 | E14: =ECE_B1!Y13 -> 100 | F14: =AVERAGE(D14:E14) -> 95.238095
A15: 3 | B15: UI23EC03 | C15: ADITYA ANAND | D15: =Th_ECE!AC15 -> 66.666667 | E15: =ECE_B1!Y14 -> 90.909091 | F15: =AVERAGE(D15:E15) -> 78.787879
A16: 4 | B16: UI23EC04 | C16: ANKIT KUMAR | D16: =Th_ECE!AC16 -> 71.428571 | E16: =ECE_B1!Y15 -> 100 | F16: =AVERAGE(D16:E16) -> 85.714286
A17: 5 | B17: UI23EC06 | C17: ARPIT CHAUHAN | D17: =Th_ECE!AC17 -> 71.428571 | E17: =ECE_B1!Y16 -> 63.636364 | F17: =AVERAGE(D17:E17) -> 67.532468
A18: 6 | B18: UI23EC07 | C18: ARPIT KHARE | D18: =Th_ECE!AC18 -> 71.428571 | E18: =ECE_B1!Y17 -> 63.636364 | F18: =AVERAGE(D18:E18) -> 67.532468
A19: 7 | B19: UI23EC08 | C19: ARYAN KUMAR | D19: =Th_ECE!AC19 -> 76.190476 | E19: =ECE_B1!Y18 -> 90.909091 | F19: =AVERAGE(D19:E19) -> 83.549784
A20: 8 | B20: UI23EC09 | C20: ARYAN TIWARI | D20: =Th_ECE!AC20 -> 71.428571 | E20: =ECE_B1!Y19 -> 72.727273 | F20: =AVERAGE(D20:E20) -> 72.077922
A21: 9 | B21: UI23EC11 | C21: AYUSH SINGH | D21: =Th_ECE!AC21 -> 71.428571 | E21: =ECE_B1!Y20 -> 72.727273 | F21: =AVERAGE(D21:E21) -> 72.077922
A22: 10 | B22: UI23EC12 | C22: BODDU SRINIVASA RAO | D22: =Th_ECE!AC22 -> 90 | E22: =ECE_B1!Y21 -> 63.636364 | F22: =AVERAGE(D22:E22) -> 76.818182
A23: 11 | B23: UI23EC13 | C23: CHETHAN SAI BILLA | D23: =Th_ECE!AC23 -> 52.380952 | E23: =ECE_B1!Y22 -> 63.636364 | F23: =AVERAGE(D23:E23) -> 58.008658
A24: 12 | B24: UI23EC14 | C24: CHIRAG KUMAR | D24: =Th_ECE!AC24 -> 90.47619 | E24: =ECE_B1!Y23 -> 100 | F24: =AVERAGE(D24:E24) -> 95.238095
... A41: 29 | B41: UI23EC34 | C41: KUNAL MAHENDRA | D41: =Th_ECE!AC41 -> 76.190476 | E41: =ECE_B1!Y40 -> 80 | F41: =AVERAGE(D41:E41) -> 78.095238
A42: 30 | B42: UI23EC35 | C42: MANASVI CHOUDHARY | D42: =Th_ECE!AC42 -> 66.666667 | E42: =ECE_B2!Z11 -> 100 | F42: =AVERAGE(D42:E42) -> 83.333333
A43: 31 | B43: UI23EC36 | C43: MANOJ KUMAWAT | D43: =Th_ECE!AC43 -> 76.190476 | E43: =ECE_B2!Z12 -> 88.888889 | F43: =AVERAGE(D43:E43) -> 82.539683
A44: 32 | B44: UI23EC37 | C44: MITULKUMAR MAGANBHAI HADIYA | D44: =Th_ECE!AC44 -> 80.952381 | E44: =ECE_B2!Z13 -> 88.888889 | F44: =AVERAGE(D44:E44) -> 84.920635
A45: 33 | B45: UI23EC40 | C45: NITIN | D45: =Th_ECE!AC45 -> 100 | E45: =ECE_B2!Z14 -> 77.777778 | F45: =AVERAGE(D45:E45) -> 88.888889
A46: 34 | B46: UI23EC41 | C46: OM SETH | D46: =Th_ECE!AC46 -> 71.428571 | E46: =ECE_B2!Z15 -> 77.777778 | F46: =AVERAGE(D46:E46) -> 74.603175
A47: 35 | B47: UI23EC42 | C47: PACHURU SUNIL | D47: =Th_ECE!AC47 -> 66.666667 | E47: =ECE_B2!Z16 -> 77.777778 | F47: =AVERAGE(D47:E47) -> 72.222222
A48: 36 | B48: UI23EC43 | C48: PALAK DWIVEDI | D48: =Th_ECE!AC48 -> 71.428571 | E48: =ECE_B2!Z17 -> 77.777778 | F48: =AVERAGE(D48:E48) -> 74.603175
A49: 37 | B49: UI23EC44 | C49: PRATEEK SINGH | D49: =Th_ECE!AC49 -> 100 | E49: =ECE_B2!Z18 -> 77.777778 | F49: =AVERAGE(D49:E49) -> 88.888889
A50: 38 | B50: UI23EC45 | C50: PREET KUMAR | D50: =Th_ECE!AC50 -> 66.666667 | E50: =ECE_B2!Z19 -> 77.777778 | F50: =AVERAGE(D50:E50) -> 72.222222
A51: 39 | B51: UI23EC46 | C51: PRIYANSH CHOUDHARY | D51: =Th_ECE!AC51 -> 76.190476 | E51: =ECE_B2!Z20 -> 77.777778 | F51: =AVERAGE(D51:E51) -> 76.984127
A52: 40 | B52: UI23EC48 | C52: RAJAT JAIN | D52: =Th_ECE!AC52 -> 90.47619 | E52: =ECE_B2!Z21 -> 88.888889 | F52: =AVERAGE(D52:E52) -> 89.68254
A53: 41 | B53: UI23EC50 | C53: RAVI | D53: =Th_ECE!AC53 -> 80.952381 | E53: =ECE_B2!Z22 -> 100 | F53: =AVERAGE(D53:E53) -> 90.47619
... A69: 58 | B69: UI23EC69 | C69: YASWANTH BHUKYA | D69: =Th_ECE!AC69 -> 100 | E69: =ECE_B2!Z38 -> 66.666667 | F69: =AVERAGE(D69:E69) -> 83.333333
A70: 59 | B70: UI22EC35 | C70: JARAPILA CHARUSHMA | D70: =Th_ECE!AC70 | E70: =ECE_B1!Y69
