Workbook

Sheet Th_CSE_SDP
A1: Indian Institute of Information Technology (IIIT), Surat
A2: Computer Science and Engineering Department
A3: B.Tech - II Semester - V
A4: Subject Name: Data Science - (CS501) - Theory
A5: Subject Coordinator: Mr Anandatheertan Srinivasan
A6: Academic Year: 2025-2026
N8: SEPT | W8: OCT | AD8: Nov | AP8: Total P | AQ8: Total A | AR8: Total | AS8: Present
A10: Sr. No | B10: Enrollment No. | C10: Name | D10: 5 | E10: 6 | F10: 8 | G10: 12 | H10: 13 | I10: 20 | J10: 21 | K10: 22 | L10: 28 | M10: 29 | N10: 3 | O10: 4 | P10: 8 | Q10: 10 | R10: 11 | S10: 12 | T10: 17 | U10: 18 | V10: 19 | W10: 7 | X10: 8 | Y10: 10 | Z10: 10 | AA10: 13 | AB10: 14 | AC10: 28 | AD10: 7 | AE10: 8 | AF10: 9 | AG10: 11 | AH10: 14 | AI10: 17 | AJ10: 20 | AK10: 21 | AL10: 24
A11: 1 | B11: UI23CS01 | C11: ABHINAV | D11: P | E11: P | F11: P | G11: A | H11: P | I11: P | J11: P | K11: P | L11: P | M11: A | N11: P | O11: P | P11: P | Q11: P | R11: P | S11: P | T11: P | U11: P | V11: P | W11: P | X11: P | Y11: P | Z11: P | AA11: P | AB11: P | AC11: P | AD11: P | AE11: P | AF11: P | AG11: P | AH11: A | AI11: P | AJ11: P | AK11: P | AL11: P | AP11: =COUNTIF(D11:AO11,"P") + COUNTIF(D11:AO11, "1") -> 32 | AQ11: =COUNTIF(D11:AO11,"A") + COUNTIF(D11:AO11,"0") -> 3 | AR11: =SUM(AP11:AQ11) -> 35 | AS11: =(AP11/AR11)*100 -> 91.428571
A12: 2 | B12: UI23CS02 | C12: ABHISHEK YADAV | D12: P | E12: P | F12: P | G12: P | H12: P | I12: P | J12: P | K12: P | L12: P | M12: P | N12: P | O12: P | P12: P | Q12: P | R12: P | S12: P | T12: P | U12: P | V12: P | W12: P | X12: P | Y12: P | Z12: P | AA12: P | AB12: P | AC12: P | AD12: P | AE12: P | AF12: P | AG12: P | AH12: A | AI12: P | AJ12: P | AK12: P | AL12: P | AP12: =COUNTIF(D12:AO12,"P") + COUNTIF(D12:AO12, "1") -> 34 | AQ12: =COUNTIF(D12:AO12,"A") + COUNTIF(D12:AO12,"0") -> 1 | AR12: =SUM(AP12:AQ12) -> 35 | AS12: =(AP12/AR12)*100 -> 97.142857
A13: 3 | B13: UI23CS03 | C13: AKHILESH SINGH | D13: P | E13: P | F13: P | G13: P | H13: A | I13: A | J13: P | K13: P | L13: P | M13: P | N13: P | O13: P | P13: P | Q13: P | R13: P | S13: P | T13: P | U13: P | V13: P | W13: P | X13: P | Y13: P | Z13: P | AA13: P | AB13: P | AC13: P | AD13: P | AE13: P | AF13: P | AG13: P | AH13: P | AI13: P | AJ13: P | AK13: P | AL13: P | AP13: =COUNTIF(D13:AO13,"P") + COUNTIF(D13:AO13, "1") -> 33 | AQ13: =COUNTIF(D13:AO13,"A") + COUNTIF(D13:AO13,"0") -> 2 | AR13: =SUM(AP13:AQ13) -> 35 | AS13: =(AP13/AR13)*100 -> 94.285714
A14: 4 | B14: UI23CS05 | C14: AMAN DUDI | D14: P | E14: P | F14: P | G14: P | H14: P | I14: P | J14: P | K14: P | L14: P | M14: P | N14: P | O14: P | P14: P | Q14: P | R14: P | S14: P | T14: P | U14: P | V14: P | W14: P | X14: P | Y14: P | Z14: P | AA14: P | AB14: P | AC14: P | AD14: P | AE14: P | AF14: P | AG14: P | AH14: P | AI14: P | AJ14: P | AK14: P | AL14: P | AP14: =COUNTIF(D14:AO14,"P") + COUNTIF(D14:AO14, "1") -> 35 | AQ14: =COUNTIF(D14:AO14,"A") + COUNTIF(D14:AO14,"0") -> 0 | AR14: =SUM(AP14:AQ14) -> 35 | AS14: =(AP14/AR14)*100 -> 100
A15: 5 | B15: UI23CS06 | C15: AMAN KUMAR | D15: P | E15: P | F15: P | G15: P | H15: P | I15: P | J15: P | K15: P | L15: A | M15: A | N15: P | O15: P | P15: P | Q15: P | R15: A | S15: P | T15: P | U15: P | V15: P | W15: P | X15: P | Y15: P | Z15: P | AA15: P | AB15: P | AC15: P | AD15: P | AE15: P | AF15: P | AG15: P | AH15: A | AI15: P | AJ15: P | AK15: P | AL15: P | AP15: =COUNTIF(D15:AO15,"P") + COUNTIF(D15:AO15, "1") -> 31 | AQ15: =COUNTIF(D15:AO15,"A") + COUNTIF(D15:AO15,"0") -> 4 | AR15: =SUM(AP15:AQ15) -> 35 | AS15: =(AP15/AR15)*100 -> 88.571429
A16: 6 | B16: UI23CS07 | C16: ANJALI | D16: P | E16: P | F16: P | G16: P | H16: P | I16: P | J16: P | K16: P | L16: P | M16: P | N16: P | O16: P | P16: P | Q16: P | R16: P | S16: P | T16: P | U16: P | V16: P | W16: P | X16: P | Y16: P | Z16: P | AA16: P | AB16: P | AC16: P | AD16: P | AE16: P | AF16: P | AG16: P | AH16: P | AI16: P | AJ16: P | AK16: P | AL16: P | AP16: =COUNTIF(D16:AO16,"P") + COUNTIF(D16:AO16, "1") -> 35 | AQ16: =COUNTIF(D16:AO16,"A") + COUNTIF(D16:AO16,"0") -> 0 | AR16: =SUM(AP16:AQ16) -> 35 | AS16: =(AP16/AR16)*100 -> 100
A17: 7 | B17: UI23CS08 | C17: ANUBHAV RAJPUT | D17: P | E17: P | F17: P | G17: P | H17: P | I17: P | J17: P | K17: P | L17: A | M17: P | N17: P | O17: P | P17: P | Q17: P | R17: P | S17: P | T17: P | U17: P | V17: P | W17: P | X17: P | Y17: P | Z17: P | AA17: P | AB17: P | AC17: P | AD17: P | AE17: P | AF17: P | AG17: P | AH17: A | AI17: P | AJ17: P | AK17: P | AL17: P | AP17: =COUNTIF(D17:AO17,"P") + COUNTIF(D17:AO17, "1") -> 33 | AQ17: =COUNTIF(D17:AO17,"A") + COUNTIF(D17:AO17,"0") -> 2 | AR17: =SUM(AP17:AQ17) -> 35 | AS17: =(AP17/AR17)*100 -> 94.285714
A18: 8 | B18: UI23CS09 | C18: AVIRAL PANDEY | D18: P | E18: P | F18: P | G18: P | H18: A | I18: P | J18: P | K18: P | L18: P | M18: P | N18: P | O18: P | P18: P | Q18: P | R18: P | S18: P | T18: P | U18: P | V18: P | W18: P | X18: P | Y18: P | Z18: P | AA18: P | AB18: P | AC18: P | AD18: P | AE18: P | AF18: P | AG18: P | AH18: P | AI18: P | AJ18: P | AK18: P | AL18: P | AP18: =COUNTIF(D18:AO18,"P") + COUNTIF(D18:AO18, "1") -> 34 | AQ18: =COUNTIF(D18:AO18,"A") + COUNTIF(D18:AO18,"0") -> 1 | AR18: =SUM(AP18:AQ18) -> 35 | AS18: =(AP18/AR18)*100 -> 97.142857
A19: 9 | B19: UI23CS10 | C19: BAPATHI VENKATA SHV REDDY | D19: P | E19: P | F19: P | G19: P | H19: P | I19: P | J19: P | K19: P | L19: P | M19: P | N19: P | O19: P | P19: P | Q19: P | R19: P | S19: P | T19: P | U19: P | V19: P | W19: P | X19: P | Y19: P | Z19: P | AA19: P | AB19: P | AC19: P | AD19: P | AE19: P | AF19: P | AG19: P | AH19: P | AI19: P | AJ19: P | AK19: P | AL19: P | AP19: =COUNTIF(D19:AO19,"P") + COUNTIF(D19:AO19, "1") -> 35 | AQ19: =COUNTIF(D19:AO19,"A") + COUNTIF(D19:AO19,"0") -> 0 | AR19: =SUM(AP19:AQ19) -> 35 | AS19: =(AP19/AR19)*100 -> 100
A20: 10 | B20: UI23CS11 | C20: BELLAM APOORVA | D20: P | E20: P | F20: P | G20: P | H20: P | I20: P | J20: P | K20: P | L20: P | M20: P | N20: P | O20: P | P20: P | Q20: P | R20: P | S20: P | T20: P | U20: P | V20: P | W20: P | X20: P | Y20: P | Z20: P | AA20: P | AB20: P | AC20: P | AD20: P | AE20: P | AF20: P | AG20: P | AH20: P | AI20: P | AJ20: P | AK20: P | AL20: P | AP20: =COUNTIF(D20:AO20,"P") + COUNTIF(D20:AO20, "1") -> 35 | AQ20: =COUNTIF(D20:AO20,"A") + COUNTIF(D20:AO20,"0") -> 0 | AR20: =SUM(AP20:AQ20) -> 35 | AS20: =(AP20/AR20)*100 -> 100
A21: 11 | B21: UI23CS12 | C21: BHUKYA LINGANNA | D21: A | E21: A | F21: A | G21: A | H21: A | I21: A | J21: A | K21: A | L21: A | M21: A | N21: A | O21: A | P21: A | Q21: A | R21: A | S21: A | T21: A | U21: A | V21: A | W21: A | X21: A | Y21: A | Z21: A | AA21: A | AB21: A | AC21: A | AD21: A | AE21: A | AF21: A | AG21: A | AH21: A | AI21: A | AJ21: A | AK21: A | AL21: A | AP21: =COUNTIF(D21:AO21,"P") + COUNTIF(D21:AO21, "1") -> 0 | AQ21: =COUNTIF(D21:AO21,"A") + COUNTIF(D21:AO21,"0") -> 35 | AR21: =SUM(AP21:AQ21) -> 35 | AS21: =(AP21/AR21)*100 -> 0
A22: 12 | B22: UI23CS13 | C22: BHUPENDRA KUMAR | D22: P | E22: P | F22: P | G22: P | H22: P | I22: P | J22: A | K22: P | L22: P | M22: P | N22: P | O22: P | P22: P | Q22: P | R22: P | S22: P | T22: P | U22: P | V22: P | W22: P | X22: P | Y22: P | Z22: P | AA22: P | AB22: P | AC22: P | AD22: P | AE22: P | AF22: P | AG22: P | AH22: P | AI22: P | AJ22: P | AK22: P | AL22: P | AP22: =COUNTIF(D22:AO22,"P") + COUNTIF(D22:AO22, "1") -> 34 | AQ22: =COUNTIF(D22:AO22,"A") + COUNTIF(D22:AO22,"0") -> 1 | AR22: =SUM(AP22:AQ22) -> 35 | AS22: =(AP22/AR22)*100 -> 97.142857
... A83: 73 | B83: UI23CS78 | C83: YUG PATEL | D83: P | E83: P | F83: P | G83: P | H83: A | I83: P | J83: P | K83: P | L83: A | M83: P | N83: P | O83: P | P83: P | Q83: P | R83: P | S83: P | T83: P | U83: P | V83: P | W83: P | X83: P | Y83: P | Z83: P | AA83: P | AB83: P | AC83: P | AD83: P | AE83: P | AF83: P | AG83: P | AH83: P | AI83: P | AJ83: P | AK83: P | AL83: P | AP83: =COUNTIF(D83:AO83,"P") + COUNTIF(D83:AO83, "1") -> 33 | AQ83: =COUNTIF(D83:AO83,"A") + COUNTIF(D83:AO83,"0") -> 2 | AR83: =SUM(AP83:AQ83) -> 35 | AS83: =(AP83/AR83)*100 -> 94.285714
A84: 74 | B84: UI22CS11 | C84: BANOTH VENKATESH | D84: P | E84: P | F84: P | G84: P | H84: P | I84: P | J84: P | K84: P | L84: A | M84: P | N84: P | O84: P | P84: P | Q84: P | R84: P | S84: P | T84: P | U84: P | V84: P | W84: P | X84: P | Y84: P | Z84: P | AA84: P | AB84: P | AC84: P | AD84: P | AE84: P | AF84: P | AG84: P | AH84: A | AI84: P | AJ84: P | AK84: P | AL84: P | AP84: 34 | AQ84: 0 | AR84: 34 | AS84: 100
A85: 75 | B85: UI22CS42 | C85: Kanvi Makwana | D85: P | E85: P | F85: P | G85: P | H85: P | I85: P | J85: P | K85: P | L85: A | M85: P | N85: P | O85: P | P85: P | Q85: P | R85: P | S85: P | T85: P | U85: P | V85: P | W85: P | X85: P | Y85: P | Z85: P | AA85: P | AB85: P | AC85: P | AD85: P | AE85: P | AF85: P | AG85: P | AH85: P | AI85: P | AJ85: P | AK85: P | AL85: P | AP85: 34 | AQ85: 0 | AR85: 34 | AS85: 100
C88: No. of Present Student | D88: =COUNTIF(D11:D87,"P") + COUNTIF(D11:D87, "1") -> 72 | E88: =COUNTIF(E11:E87,"P") + COUNTIF(E11:E87, "1") -> 72 | F88: =COUNTIF(F11:F87,"P") + COUNTIF(F11:F87, "1") -> 71 | G88: =COUNTIF(G11:G87,"P") + COUNTIF(G11:G87, "1") -> 70 | H88: =COUNTIF(H11:H87,"P") + COUNTIF(H11:H87, "1") -> 68 | I88: =COUNTIF(I11:I87,"P") + COUNTIF(I11:I87, "1") -> 67 | J88: =COUNTIF(J11:J87,"P") + COUNTIF(J11:J87, "1") -> 66 | K88: =COUNTIF(K11:K87,"P") + COUNTIF(K11:K87, "1") -> 67 | ... R88: =COUNTIF(R11:R87,"P") + COUNTIF(R11:R87, "1") -> 71 | W88: =COUNTIF(W11:W87,"P") + COUNTIF(W11:W87, "1") -> 71 | X88: =COUNTIF(X11:X87,"P") + COUNTIF(X11:X87, "1") -> 72 | Z88: =COUNTIF(Z11:Z87,"P") + COUNTIF(Z11:Z87, "1") -> 71 | AA88: =COUNTIF(AA11:AA87,"P") + COUNTIF(AA11:AA87, "1") -> 72 | AB88: =COUNTIF(AB11:AB87,"P") + COUNTIF(AB11:AB87, "1") -> 72 | AC88: =COUNTIF(AC11:AC87,"P") + COUNTIF(AC11:AC87, "1") -> 71 | AD88: =COUNTIF(AD11:AD87,"P") + COUNTIF(AD11:AD87, "1") -> 69 | AE88: =COUNTIF(AE11:AE87,"P") + COUNTIF(AE11:AE87, "1") -> 69 | AF88: =COUNTIF(AF11:AF87,"P") + COUNTIF(AF11:AF87, "1") -> 71 | AG88: =COUNTIF(AG11:AG87,"P") + COUNTIF(AG11:AG87, "1") -> 71 | AH88: 65 | AI88: =COUNTIF(AI11:AI87,"P") + COUNTIF(AI11:AI87, "1") -> 72 | AJ88: =COUNTIF(AJ11:AJ87,"P") + COUNTIF(AJ11:AJ87, "1") -> 71 | AK88: =COUNTIF(AK11:AK87,"P") + COUNTIF(AK11:AK87, "1") -> 72 | AL88: =COUNTIF(AL11:AL87,"P") + COUNTIF(AL11:AL87, "1") -> 72 | AM88: =COUNTIF(AM11:AM87,"P") + COUNTIF(AM11:AM87, "1") -> 0 | AN88: =COUNTIF(AN11:AN87,"P") + COUNTIF(AN11:AN87, "1") -> 0 | AO88: =COUNTIF(AO11:AO87,"P") + COUNTIF(AO11:AO87, "1") -> 0
C89: No. of Absent Student | D89: =COUNTIF(D11:D87,"A") + COUNTIF(D11:D87, "1") -> 3 | E89: =COUNTIF(E11:E87,"A") + COUNTIF(E11:E87, "1") -> 3 | F89: =COUNTIF(F11:F87,"A") + COUNTIF(F11:F87, "1") -> 4 | G89: =COUNTIF(G11:G87,"A") + COUNTIF(G11:G87, "1") -> 5 | H89: =COUNTIF(H11:H87,"A") + COUNTIF(H11:H87, "1") -> 7 | I89: =COUNTIF(I11:I87,"A") + COUNTIF(I11:I87, "1") -> 8 | J89: =COUNTIF(J11:J87,"A") + COUNTIF(J11:J87, "1") -> 9 | N89: =COUNTIF(N11:N87,"A") + COUNTIF(N11:N87, "1") -> 4 | O89: =COUNTIF(O11:O87,"A") + COUNTIF(O11:O87, "1") -> 7 | P89: =COUNTIF(P11:P87,"A") + COUNTIF(P11:P87, "1") -> 5 | Q89: =COUNTIF(Q11:Q87,"A") + COUNTIF(Q11:Q87, "1") -> 3 | R89: =COUNTIF(R11:R87,"A") + COUNTIF(R11:R87, "1") -> 4 | W89: =COUNTIF(W11:W87,"A") + COUNTIF(W11:W87, "1") -> 4 | X89: =COUNTIF(X11:X87,"A") + COUNTIF(X11:X87, "1") -> 3 | Z89: =COUNTIF(Z11:Z87,"A") + COUNTIF(Z11:Z87, "1") -> 4 | AA89: =COUNTIF(AA11:AA87,"A") + COUNTIF(AA11:AA87, "1") -> 3 | AB89: =COUNTIF(AB11:AB87,"A") + COUNTIF(AB11:AB87, "1") -> 3 | AC89: =COUNTIF(AC11:AC87,"A") + COUNTIF(AC11:AC87, "1") -> 4 | AD89: =COUNTIF(AD11:AD87,"A") + COUNTIF(AD11:AD87, "1") -> 6 | AE89: =COUNTIF(AE11:AE87,"A") + COUNTIF(AE11:AE87, "1") -> 6 | AF89: =COUNTIF(AF11:AF87,"A") + COUNTIF(AF11:AF87, "1") -> 4 | AG89: =COUNTIF(AG11:AG87,"A") + COUNTIF(AG11:AG87, "1") -> 4 | AH89: 10 | AI89: =COUNTIF(AI11:AI87,"A") + COUNTIF(AI11:AI87, "1") -> 3 | AJ89: =COUNTIF(AJ11:AJ87,"A") + COUNTIF(AJ11:AJ87, "1") -> 4 | AK89: =COUNTIF(AK11:AK87,"A") + COUNTIF(AK11:AK87, "1") -> 3 | AL89: =COUNTIF(AL11:AL87,"A") + COUNTIF(AL11:AL87, "1") -> 3 | AM89: =COUNTIF(AM11:AM87,"A") + COUNTIF(AM11:AM87, "1") -> 0 | AN89: =COUNTIF(AN11:AN87,"A") + COUNTIF(AN11:AN87, "1") -> 0 | AO89: =COUNTIF(AO11:AO87,"A") + COUNTIF(AO11:AO87, "1") -> 0

Sheet LAB_B1
A1: Indian Institute of Information Technology (IIIT), Surat
A2: Computer Science and Engineering Department
A3: B.Tech - II Semester - V
A4: Subject Name: Data Science - (CS501) - Lab_B1
A5: Subject Coordinator: Mr Anandatheertan Srinivasan
A6: Academic Year: 2025-2026
D9: August | G9: September | J9: Oct | M9: Nov | O9: Total P | P9: Total A | Q9: Total | R9: Present
A10: Sr. No | B10: Enrollment No. | C10: Name | D10: 11 | E10: 18 | F10: 26 | G10: 1 | H10: 8 | I10: 15 | J10: 6 | K10: 13 | L10: 27 | M10: 3 | N10: 21
A11: 1 | B11: UI23CS01 | C11: ABHINAV | D11: P | E11: P | F11: P | G11: P | H11: P | I11: P | J11: P | K11: P | L11: P | M11: P | N11: P | O11: =COUNTIF(D11:M11,"P") + COUNTIF(D11:M11, "1") -> 10 | P11: =COUNTIF(D11:M11,"A") + COUNTIF(D11:M11,"0") -> 0 | Q11: =SUM(O11:P11) -> 10 | R11: =(O11/Q11)*100 -> 100
A12: 2 | B12: UI23CS02 | C12: ABHISHEK YADAV | D12: P | E12: P | F12: P | G12: P | H12: P | I12: P | J12: P | K12: P | L12: P | M12: P | N12: P | O12: =COUNTIF(D12:M12,"P") + COUNTIF(D12:M12, "1") -> 10 | P12: =COUNTIF(D12:M12,"A") + COUNTIF(D12:M12,"0") -> 0 | Q12: =SUM(O12:P12) -> 10 | R12: =(O12/Q12)*100 -> 100
A13: 3 | B13: UI23CS03 | C13: AKHILESH SINGH | D13: P | E13: P | F13: P | G13: P | H13: P | I13: P | J13: P | K13: P | L13: P | M13: P | N13: P | O13: =COUNTIF(D13:M13,"P") + COUNTIF(D13:M13, "1") -> 10 | P13: =COUNTIF(D13:M13,"A") + COUNTIF(D13:M13,"0") -> 0 | Q13: =SUM(O13:P13) -> 10 | R13: =(O13/Q13)*100 -> 100
A14: 4 | B14: UI23CS05 | C14: AMAN DUDI | D14: P | E14: A | F14: P | G14: P | H14: P | I14: P | J14: P | K14: P | L14: A | M14: P | N14: P | O14: =COUNTIF(D14:M14,"P") + COUNTIF(D14:M14, "1") -> 8 | P14: =COUNTIF(D14:M14,"A") + COUNTIF(D14:M14,"0") -> 2 | Q14: =SUM(O14:P14) -> 10 | R14: =(O14/Q14)*100 -> 80
A15: 5 | B15: UI23CS06 | C15: AMAN KUMAR | D15: P | E15: P | F15: P | G15: P | H15: P | I15: P | J15: P | K15: P | L15: P | M15: P | N15: P | O15: =COUNTIF(D15:M15,"P") + COUNTIF(D15:M15, "1") -> 10 | P15: =COUNTIF(D15:M15,"A") + COUNTIF(D15:M15,"0") -> 0 | Q15: =SUM(O15:P15) -> 10 | R15: =(O15/Q15)*100 -> 100
A16: 6 | B16: UI23CS07 | C16: ANJALI | D16: P | E16: P | F16: P | G16: P | H16: P | I16: P | J16: P | K16: P | L16: P | M16: P | N16: P | O16: =COUNTIF(D16:M16,"P") + COUNTIF(D16:M16, "1") -> 10 | P16: =COUNTIF(D16:M16,"A") + COUNTIF(D16:M16,"0") -> 0 | Q16: =SUM(O16:P16) -> 10 | R16: =(O16/Q16)*100 -> 100
A17: 7 | B17: UI23CS08 | C17: ANUBHAV RAJPUT | D17: P | E17: P | F17: P | G17: P | H17: A | I17: P | J17: P | K17: P | L17: P | M17: P | N17: P | O17: =COUNTIF(D17:M17,"P") + COUNTIF(D17:M17, "1") -> 9 | P17: =COUNTIF(D17:M17,"A") + COUNTIF(D17:M17,"0") -> 1 | Q17: =SUM(O17:P17) -> 10 | R17: =(O17/Q17)*100 -> 90
A18: 8 | B18: UI23CS09 | C18: AVIRAL PANDEY | D18: P | E18: P | F18: P | G18: P | H18: P | I18: P | J18: P | K18: P | L18: P | M18: P | N18: P | O18: =COUNTIF(D18:M18,"P") + COUNTIF(D18:M18, "1") -> 10 | P18: =COUNTIF(D18:M18,"A") + COUNTIF(D18:M18,"0") -> 0 | Q18: =SUM(O18:P18) -> 10 | R18: =(O18/Q18)*100 -> 100
A19: 9 | B19: UI23CS10 | C19: BAPATHI VENKATA SHV REDDY | D19: P | E19: P | F19: P | G19: P | H19: P | I19: P | J19: P | K19: P | L19: P | M19: P | N19: P | O19: =COUNTIF(D19:M19,"P") + COUNTIF(D19:M19, "1") -> 10 | P19: =COUNTIF(D19:M19,"A") + COUNTIF(D19:M19,"0") -> 0 | Q19: =SUM(O19:P19) -> 10 | R19: =(O19/Q19)*100 -> 100
A20: 10 | B20: UI23CS11 | C20: BELLAM APOORVA | D20: P | E20: P | F20: P | G20: P | H20: P | I20: P | J20: P | K20: P | L20: P | M20: P | N20: P | O20: =COUNTIF(D20:M20,"P") + COUNTIF(D20:M20, "1") -> 10 | P20: =COUNTIF(D20:M20,"A") + COUNTIF(D20:M20,"0") -> 0 | Q20: =SUM(O20:P20) -> 10 | R20: =(O20/Q20)*100 -> 100
A21: 11 | B21: UI23CS12 | C21: BHUKYA LINGANNA | D21: A | E21: A | F21: A | G21: A | H21: A | I21: A | J21: A | K21: A | L21: A | M21: A | N21: A | O21: =COUNTIF(D21:M21,"P") + COUNTIF(D21:M21, "1") -> 0 | P21: =COUNTIF(D21:M21,"A") + COUNTIF(D21:M21,"0") -> 10 | Q21: =SUM(O21:P21) -> 10 | R21: =(O21/Q21)*100 -> 0
A22: 12 | B22: UI23CS13 | C22: BHUPENDRA KUMAR | D22: P | E22: P | F22: P | G22: P | H22: P | I22: P | J22: P | K22: P | L22: P | M22: P | N22: P | O22: =COUNTIF(D22:M22,"P") + COUNTIF(D22:M22, "1") -> 10 | P22: =COUNTIF(D22:M22,"A") + COUNTIF(D22:M22,"0") -> 0 | Q22: =SUM(O22:P22) -> 10 | R22: =(O22/Q22)*100 -> 100
... A47: 37 | B47: UI23CS40 | C47: MAYANK KUMAR SAGAR | D47: P | E47: P | F47: P | G47: P | H47: P | I47: P | J47: P | K47: P | L47: P | M47: P | N47: P | O47: =COUNTIF(D47:M47,"P") + COUNTIF(D47:M47, "1") -> 10 | P47: =COUNTIF(D47:M47,"A") + COUNTIF(D47:M47,"0") -> 0 | Q47: =SUM(O47:P47) -> 10 | R47: =(O47/Q47)*100 -> 100
C51: No. of Present Student | D51: =COUNTIF(D11:D50,"P") + COUNTIF(D11:D50, "1") -> 36 | E51: =COUNTIF(E11:E50,"P") + COUNTIF(E11:E50, "1") -> 35 | G51: =COUNTIF(G11:G50,"P") + COUNTIF(G11:G50, "1") -> 35 | J51: =COUNTIF(J11:J50,"P") + COUNTIF(J11:J50, "1") -> 36 | K51: =COUNTIF(K11:K50,"P") + COUNTIF(K11:K50, "1") -> 31 | L51: =COUNTIF(L11:L50,"P") + COUNTIF(L11:L50, "1") -> 34 | M51: =COUNTIF(M11:M50,"P") + COUNTIF(M11:M50, "1") -> 36
C52: No. of Absent Student | D52: =COUNTIF(D12:D50,"A") + COUNTIF(D12:D50, "1") -> 1 | E52: =COUNTIF(E12:E50,"A") + COUNTIF(E12:E50, "1") -> 2 | G52: =COUNTIF(G12:G50,"A") + COUNTIF(G12:G50, "1") -> 2 | J52: =COUNTIF(J12:J50,"A") + COUNTIF(J12:J50, "1") -> 1 | K52: =COUNTIF(K12:K50,"A") + COUNTIF(K12:K50, "1") -> 6 | L52: =COUNTIF(L12:L50,"A") + COUNTIF(L12:L50, "1") -> 3 | M52: =COUNTIF(M12:M50,"A") + COUNTIF(M12:M50, "1") -> 1

Sheet LAB_B2
A1: Indian Institute of Information Technology (IIIT), Surat
A2: Computer Science and Engineering Department
A3: B.Tech - II Semester - V
A4: Subject Name: Data Science - (CS501) - Lab_B2
A5: Subject Coordinator: Mr Anandatheertan Srinivasan
A6: Academic Year: 2025-2026
C8: Hugging Face Spaces Gradio Streamlit
D9: AUG | G9: Sep | J9: Oct | L9: Nov | O9: Total P | P9: Total A | Q9: Total | R9: Present
A10: Sr. No | B10: Enrollment No. | C10: Name | D10: 12 | E10: 19 | F10: 30 | G10: 2 | H10: 9 | I10: 16 | J10: 14 | K10: 28 | L10: 4 | M10: 21 | N10: 28
A11: 38 | B11: UI23CS41 | C11: MEET MANOJBHAI PATEL | D11: P | E11: P | F11: A | G11: P | H11: P | I11: P | J11: P | K11: P | L11: P | M11: P | O11: =COUNTIF(D11:M11,"P")+COUNTIF(D11:M11,"1") -> 9 | P11: =COUNTIF(D11:M11,"A")+COUNTIF(D11:M11,"0") -> 1 | Q11: =SUM(O11:P11) -> 10 | R11: =(O11/Q11)*100 -> 90
A12: 39 | B12: UI23CS42 | C12: MEET PARESH PARMAR | D12: P | E12: P | F12: P | G12: P | H12: P | I12: P | J12: P | K12: P | L12: P | M12: P | O12: =COUNTIF(D12:M12,"P")+COUNTIF(D12:M12,"1") -> 10 | P12: =COUNTIF(D12:M12,"A")+COUNTIF(D12:M12,"0") -> 0 | Q12: =SUM(O12:P12) -> 10 | R12: =(O12/Q12)*100 -> 100
A13: 40 | B13: UI23CS43 | C13: MEET SHAH | D13: A | E13: A | F13: A | G13: A | H13: A | I13: A | J13: A | K13: A | L13: A | M13: A | O13: =COUNTIF(D13:M13,"P")+COUNTIF(D13:M13,"1") -> 0 | P13: =COUNTIF(D13:M13,"A")+COUNTIF(D13:M13,"0") -> 10 | Q13: =SUM(O13:P13) -> 10 | R13: =(O13/Q13)*100 -> 0
A14: 41 | B14: UI23CS44 | C14: MEETIKSHA | D14: P | E14: P | F14: P | G14: P | H14: P | I14: P | J14: P | K14: P | L14: P | M14: P | O14: =COUNTIF(D14:M14,"P")+COUNTIF(D14:M14,"1") -> 10 | P14: =COUNTIF(D14:M14,"A")+COUNTIF(D14:M14,"0") -> 0 | Q14: =SUM(O14:P14) -> 10 | R14: =(O14/Q14)*100 -> 100
A15: 42 | B15: UI23CS45 | C15: MOHAMMAD SAQUIB | D15: P | E15: P | F15: P | G15: P | H15: P | I15: P | J15: A | K15: P | L15: P | M15: P | O15: =COUNTIF(D15:M15,"P")+COUNTIF(D15:M15,"1") -> 9 | P15: =COUNTIF(D15:M15,"A")+COUNTIF(D15:M15,"0") -> 1 | Q15: =SUM(O15:P15) -> 10 | R15: =(O15/Q15)*100 -> 90
A16: 43 | B16: UI23CS46 | C16: MUDAVATH PRAVEEN NAYAK | D16: A | E16: A | F16: A | G16: A | H16: A | I16: A | J16: A | K16: A | L16: A | M16: A | O16: =COUNTIF(D16:M16,"P")+COUNTIF(D16:M16,"1") -> 0 | P16: =COUNTIF(D16:M16,"A")+COUNTIF(D16:M16,"0") -> 10 | Q16: =SUM(O16:P16) -> 10 | R16: =(O16/Q16)*100 -> 0
A17: 44 | B17: UI23CS47 | C17: NAGANDLA SIDDHARRDHAA | D17: P | E17: P | F17: P | G17: P | H17: P | I17: P | J17: P | K17: P | L17: P | M17: P | O17: =COUNTIF(D17:M17,"P")+COUNTIF(D17:M17,"1") -> 10 | P17: =COUNTIF(D17:M17,"A")+COUNTIF(D17:M17,"0") -> 0 | Q17: =SUM(O17:P17) -> 10 | R17: =(O17/Q17)*100 -> 100
A18: 45 | B18: UI23CS48 | C18: NITISH | D18: P | E18: P | F18: P | G18: P | H18: P | I18: P | J18: P | K18: P | L18: P | M18: P | O18: =COUNTIF(D18:M18,"P")+COUNTIF(D18:M18,"1") -> 10 | P18: =COUNTIF(D18:M18,"A")+COUNTIF(D18:M18,"0") -> 0 | Q18: =SUM(O18:P18) -> 10 | R18: =(O18/Q18)*100 -> 100
A19: 46 | B19: UI23CS49 | C19: PANKAJ KUMAR | D19: P | E19: P | F19: P | G19: P | H19: P | I19: P | J19: P | K19: P | L19: P | M19: P | O19: =COUNTIF(D19:M19,"P")+COUNTIF(D19:M19,"1") -> 10 | P19: =COUNTIF(D19:M19,"A")+COUNTIF(D19:M19,"0") -> 0 | Q19: =SUM(O19:P19) -> 10 | R19: =(O19/Q19)*100 -> 100
A20: 47 | B20: UI23CS50 | C20: PERAM PRIYATHAM REDDY | D20: P | E20: P | F20: P | G20: P | H20: P | I20: P | J20: P | K20: A | L20: P | M20: P | O20: =COUNTIF(D20:M20,"P")+COUNTIF(D20:M20,"1") -> 9 | P20: =COUNTIF(D20:M20,"A")+COUNTIF(D20:M20,"0") -> 1 | Q20: =SUM(O20:P20) -> 10 | R20: =(O20/Q20)*100 -> 90
A21: 48 | B21: UI23CS51 | C21: PIPALIYA MOHIT SHAILESHBHAI | D21: P | E21: A | F21: P | G21: P | H21: P | I21: P | J21: P | K21: P | L21: P | M21: P | O21: =COUNTIF(D21:M21,"P")+COUNTIF(D21:M21,"1") -> 9 | P21: =COUNTIF(D21:M21,"A")+COUNTIF(D21:M21,"0") -> 1 | Q21: =SUM(O21:P21) -> 10 | R21: =(O21/Q21)*100 -> 90
A22: 49 | B22: UI23CS52 | C22: PRAMITH SAI THALLA | D22: P | E22: P | F22: P | G22: P | H22: P | I22: P | J22: P | K22: P | L22: P | M22: P | O22: =COUNTIF(D22:M22,"P")+COUNTIF(D22:M22,"1") -> 10 | P22: =COUNTIF(D22:M22,"A")+COUNTIF(D22:M22,"0") -> 0 | Q22: =SUM(O22:P22) -> 10 | R22: =(O22/Q22)*100 -> 100
... A47: 74 | B47: UI22CS11 | C47: BANOTH VENKATESH | D47: P | E47: P | F47: P | G47: P | H47: P | I47: P | J47: P | K47: P | L47: P | M47: P | O47: =COUNTIF(D47:M47,"P")+COUNTIF(D47:M47,"1") -> 10 | P47: =COUNTIF(D47:M47,"A")+COUNTIF(D47:M47,"0") -> 0 | Q47: =SUM(O47:P47) -> 10 | R47: =(O47/Q47)*100 -> 100
A48: 75 | B48: UI22CS42 | C48: Kanvi Makwana | D48: P | E48: P | F48: P | G48: P | H48: P | I48: P | J48: P | K48: P | L48: P | M48: P | O48: 0 | P48: 0 | Q48: 0 | R48: #DIV/0!
C53: No. of Present Student | D53: =COUNTIF(D10:D52,"P") + COUNTIF(D10:D52, "1") -> 36 | E53: =COUNTIF(E10:E52,"P") + COUNTIF(E10:E52, "1") -> 35 | F53: =COUNTIF(F10:F52,"P") + COUNTIF(F10:F52, "1") -> 34 | G53: =COUNTIF(G10:G52,"P") + COUNTIF(G10:G52, "1") -> 36 | H53: =COUNTIF(H10:H52,"P") + COUNTIF(H10:H52, "1") -> 34 | J53: =COUNTIF(J10:J52,"P") + COUNTIF(J10:J52, "1") -> 30 | K53: =COUNTIF(K10:K52,"P") + COUNTIF(K10:K52, "1") -> 33 | L53: =COUNTIF(L10:L52,"P") + COUNTIF(L10:L52, "1") -> 36 | M53: =COUNTIF(M10:M52,"P") + COUNTIF(M10:M52, "1") -> 36 | O53: =COUNTIF(O10:O52,"P") + COUNTIF(O10:O52, "1") -> 0 | P53: =COUNTIF(P10:P52,"P") + COUNTIF(P10:P52, "1") -> 14 | Q53: =COUNTIF(Q10:Q52,"P") + COUNTIF(Q10:Q52, "1") -> 0
C54: No. of Absent Student | D54: =COUNTIF(D11:D52,"A") + COUNTIF(D11:D52, "1") -> 2 | E54: =COUNTIF(E11:E52,"A") + COUNTIF(E11:E52, "1") -> 3 | F54: =COUNTIF(F11:F52,"A") + COUNTIF(F11:F52, "1") -> 4 | G54: =COUNTIF(G11:G52,"A") + COUNTIF(G11:G52, "1") -> 2 | H54: =COUNTIF(H11:H52,"A") + COUNTIF(H11:H52, "1") -> 4 | J54: =COUNTIF(J11:J52,"A") + COUNTIF(J11:J52, "1") -> 8 | K54: =COUNTIF(K11:K52,"A") + COUNTIF(K11:K52, "1") -> 5 | L54: =COUNTIF(L11:L52,"A") + COUNTIF(L11:L52, "1") -> 2 | M54: =COUNTIF(M11:M52,"A") + COUNTIF(M11:M52, "1") -> 2 | O54: =COUNTIF(O11:O52,"A") + COUNTIF(O11:O52, "1") -> 0 | P54: =COUNTIF(P11:P52,"A") + COUNTIF(P11:P52, "1") -> 14 | Q54: =COUNTIF(Q11:Q52,"A") + COUNTIF(Q11:Q52, "1") -> 0

Sheet Total_CSE
A1: Indian Institute of Information Technology (IIIT), Surat
A2: Computer Science and Engineering Department
A3: B.Tech - II Semester - V
A4: Subject Name: Data Science - (CS501)
A5: Subject Coordinator: Mr Anandatheertan Srinivasan
A6: Academic Year: 2025-2026
D9: Attended_Lec_SDP | E9: Attended_Lec_AB | F9: Total_Attended_Lec | G9: Attended_Lab | H9: Total Lec | I9: Total_Attendance | J9: Total Lab | K9: Total_Lec_Lab | L9: Present Percentage Theory (%) | M9: Present Percentage Lab (%) | N9: Present Percentage (%)
A12: Sr. No | B12: Enrollment No. | C12: Name
A13: 1 | B13: UI23CS01 | C13: ABHINAV | D13: =Th_CSE_SDP!AP11 -> 32 | E13: =th_cse_ab!AC11 -> #REF! | F13: =D13 -> 32 | G13: =LAB_B1!O11 -> 10 | H13: =Th_CSE_SDP!AR11 -> 35 | I13: =SUM(F13:G13) -> 42 | J13: =LAB_B1!Q11 -> 10 | K13: =H13+J13 -> 45 | L13: =(F13/H13)*100 -> 91.428571 | M13: =(G13/J13)*100 -> 100 | N13: =(I13/K13)*100 -> 93.333333
A14: 2 | B14: UI23CS02 | C14: ABHISHEK YADAV | D14: =Th_CSE_SDP!AP12 -> 34 | E14: =th_cse_ab!AC11 -> #REF! | F14: =D14 -> 34 | G14: =LAB_B1!O12 -> 10 | H14: =Th_CSE_SDP!AR12 -> 35 | I14: =SUM(F14:G14) -> 44 | J14: =LAB_B1!Q12 -> 10 | K14: =H14+J14 -> 45 | L14: =(F14/H14)*100 -> 97.142857 | M14: =(G14/J14)*100 -> 100 | N14: =(I14/K14)*100 -> 97.777778
A15: 3 | B15: UI23CS03 | C15: AKHILESH SINGH | D15: =Th_CSE_SDP!AP13 -> 33 | E15: =th_cse_ab!AC11 -> #REF! | F15: =D15 -> 33 | G15: =LAB_B1!O13 -> 10 | H15: =Th_CSE_SDP!AR13 -> 35 | I15: =SUM(F15:G15) -> 43 | J15: =LAB_B1!Q13 -> 10 | K15: =H15+J15 -> 45 | L15: =(F15/H15)*100 -> 94.285714 | M15: =(G15/J15)*100 -> 100 | N15: =(I15/K15)*100 -> 95.555556
A16: 4 | B16: UI23CS05 | C16: AMAN DUDI | D16: =Th_CSE_SDP!AP14 -> 35 | E16: =th_cse_ab!AC11 -> #REF! | F16: =D16 -> 35 | G16: =LAB_B1!O14 -> 8 | H16: =Th_CSE_SDP!AR14 -> 35 | I16: =SUM(F16:G16) -> 43 | J16: =LAB_B1!Q14 -> 10 | K16: =H16+J16 -> 45 | L16: =(F16/H16)*100 -> 100 | M16: =(G16/J16)*100 -> 80 | N16: =(I16/K16)*100 -> 95.555556
A17: 5 | B17: UI23CS06 | C17: AMAN KUMAR | D17: =Th_CSE_SDP!AP15 -> 31 | E17: =th_cse_ab!AC11 -> #REF! | F17: =D17 -> 31 | G17: =LAB_B1!O15 -> 10 | H17: =Th_CSE_SDP!AR15 -> 35 | I17: =SUM(F17:G17) -> 41 | J17: =LAB_B1!Q15 -> 10 | K17: =H17+J17 -> 45 | L17: =(F17/H17)*100 -> 88.571429 | M17: =(G17/J17)*100 -> 100 | N17: =(I17/K17)*100 -> 91.111111
A18: 6 | B18: UI23CS07 | C18: ANJALI | D18: =Th_CSE_SDP!AP16 -> 35 | E18: =th_cse_ab!AC11 -> #REF! | F18: =D18 -> 35 | G18: =LAB_B1!O16 -> 10 | H18: =Th_CSE_SDP!AR16 -> 35 | I18: =SUM(F18:G18) -> 45 | J18: =LAB_B1!Q16 -> 10 | K18: =H18+J18 -> 45 | L18: =(F18/H18)*100 -> 100 | M18: =(G18/J18)*100 -> 100 | N18: =(I18/K18)*100 -> 100
A19: 7 | B19: UI23CS08 | C19: ANUBHAV RAJPUT | D19: =Th_CSE_SDP!AP17 -> 33 | E19: =th_cse_ab!AC11 -> #REF! | F19: =D19 -> 33 | G19: =LAB_B1!O17 -> 9 | H19: =Th_CSE_SDP!AR17 -> 35 | I19: =SUM(F19:G19) -> 42 | J19: =LAB_B1!Q17 -> 10 | K19: =H19+J19 -> 45 | L19: =(F19/H19)*100 -> 94.285714 | M19: =(G19/J19)*100 -> 90 | N19: =(I19/K19)*100 -> 93.333333
A20: 8 | B20: UI23CS09 | C20: AVIRAL PANDEY | D20: =Th_CSE_SDP!AP18 -> 34 | E20: =th_cse_ab!AC11 -> #REF! | F20: =D20 -> 34 | G20: =LAB_B1!O18 -> 10 | H20: =Th_CSE_SDP!AR18 -> 35 | I20: =SUM(F20:G20) -> 44 | J20: =LAB_B1!Q18 -> 10 | K20: =H20+J20 -> 45 | L20: =(F20/H20)*100 -> 97.142857 | M20: =(G20/J20)*100 -> 100 | N20: =(I20/K20)*100 -> 97.777778
A21: 9 | B21: UI23CS10 | C21: BAPATHI VENKATA SHV REDDY | D21: =Th_CSE_SDP!AP19 -> 35 | E21: =th_cse_ab!AC11 -> #REF! | F21: =D21 -> 35 | G21: =LAB_B1!O19 -> 10 | H21: =Th_CSE_SDP!AR19 -> 35 | I21: =SUM(F21:G21) -> 45 | J21: =LAB_B1!Q19 -> 10 | K21: =H21+J21 -> 45 | L21: =(F21/H21)*100 -> 100 | M21: =(G21/J21)*100 -> 100 | N21: =(I21/K21)*100 -> 100
A22: 10 | B22: UI23CS11 | C22: BELLAM APOORVA | D22: =Th_CSE_SDP!AP20 -> 35 | E22: =th_cse_ab!AC11 -> #REF! | F22: =D22 -> 35 | G22: =LAB_B1!O20 -> 10 | H22: =Th_CSE_SDP!AR20 -> 35 | I22: =SUM(F22:G22) -> 45 | J22: =LAB_B1!Q20 -> 10 | K22: =H22+J22 -> 45 | L22: =(F22/H22)*100 -> 100 | M22: =(G22/J22)*100 -> 100 | N22: =(I22/K22)*100 -> 100
A23: 11 | B23: UI23CS12 | C23: BHUKYA LINGANNA | D23: =Th_CSE_SDP!AP21 -> 0 | E23: =th_cse_ab!AC11 -> #REF! | F23: =D23 -> 0 | G23: =LAB_B1!O21 -> 0 | H23: =Th_CSE_SDP!AR21 -> 35 | I23: =SUM(F23:G23) -> 0 | J23: =LAB_B1!Q21 -> 10 | K23: =H23+J23 -> 45 | L23: =(F23/H23)*100 -> 0 | M23: =(G23/J23)*100 -> 0 | N23: =(I23/K23)*100 -> 0
A24: 12 | B24: UI23CS13 | C24: BHUPENDRA KUMAR | D24: =Th_CSE_SDP!AP22 -> 34 | E24: =th_cse_ab!AC11 -> #REF! | F24: =D24 -> 34 | G24: =LAB_B1!O22 -> 10 | H24: =Th_CSE_SDP!AR22 -> 35 | I24: =SUM(F24:G24) -> 44 | J24: =LAB_B1!Q22 -> 10 | K24: =H24+J24 -> 45 | L24: =(F24/H24)*100 -> 97.142857 | M24: =(G24/J24)*100 -> 100 | N24: =(I24/K24)*100 -> 97.777778
A25: 13 | B25: UI23CS16 | C25: DARSHAN DIXIT | D25: =Th_CSE_SDP!AP23 -> 35 | E25: =th_cse_ab!AC11 -> #REF! | F25: =D25 -> 35 | G25: =LAB_B1!O23 -> 9 | H25: =Th_CSE_SDP!AR23 -> 35 | I25: =SUM(F25:G25) -> 44 | J25: =LAB_B1!Q23 -> 10 | K25: =H25+J25 -> 45 | L25: =(F25/H25)*100 -> 100 | M25: =(G25/J25)*100 -> 90 | N25: =(I25/K25)*100 -> 97.777778
A26: 14 | B26: UI23CS17 | C26: DEEPAK SINGH | D26: =Th_CSE_SDP!AP24 -> 34 | E26: =th_cse_ab!AC11 -> #REF! | F26: =D26 -> 34 | G26: =LAB_B1!O24 -> 10 | H26: =Th_CSE_SDP!AR24 -> 35 | I26: =SUM(F26:G26) -> 44 | J26: =LAB_B1!Q24 -> 10 | K26: =H26+J26 -> 45 | L26: =(F26/H26)*100 -> 97.142857 | M26: =(G26/J26)*100 -> 100 | N26: =(I26/K26)*100 -> 97.777778
A27: 15 | B27: UI23CS18 | C27: DEEPESH DANGI | D27: =Th_CSE_SDP!AP25 -> 35 | E27: =th_cse_ab!AC11 -> #REF! | F27: =D27 -> 35 | G27: =LAB_B1!O25 -> 10 | H27: =Th_CSE_SDP!AR25 -> 35 | I27: =SUM(F27:G27) -> 45 | J27: =LAB_B1!Q25 -> 10 | K27: =H27+J27 -> 45 | L27: =(F27/H27)*100 -> 100 | M27: =(G27/J27)*100 -> 100 | N27: =(I27/K27)*100 -> 100
A28: 16 | B28: UI23CS19 | C28: DHRUV RAGHAV | D28: =Th_CSE_SDP!AP26 -> 31 | E28: =th_cse_ab!AC11 -> #REF! | F28: =D28 -> 31 | G28: =LAB_B1!O26 -> 10 | H28: =Th_CSE_SDP!AR26 -> 35 | I28: =SUM(F28:G28) -> 41 | J28: =LAB_B1!Q26 -> 10 | K28: =H28+J28 -> 45 | L28: =(F28/H28)*100 -> 88.571429 | M28: =(G28/J28)*100 -> 100 | N28: =(I28/K28)*100 -> 91.111111
A29: 17 | B29: UI23CS20 | C29: DINESH KUMAR | D29: =Th_CSE_SDP!AP27 -> 35 | E29: =th_cse_ab!AC11 -> #REF! | F29: =D29 -> 35 | G29: =LAB_B1!O27 -> 10 | H29: =Th_CSE_SDP!AR27 -> 35 | I29: =SUM(F29:G29) -> 45 | J29: =LAB_B1!Q27 -> 10 | K29: =H29+J29 -> 45 | L29: =(F29/H29)*100 -> 100 | M29: =(G29/J29)*100 -> 100 | N29: =(I29/K29)*100 -> 100
A30: 18 | B30: UI23CS21 | C30: FARAAZ AHMAD | D30: =Th_CSE_SDP!AP28 -> 35 | E30: =th_cse_ab!AC11 -> #REF! | F30: =D30 -> 35 | G30: =LAB_B1!O28 -> 10 | H30: =Th_CSE_SDP!AR28 -> 35 | I30: =SUM(F30:G30) -> 45 | J30: =LAB_B1!Q28 -> 10 | K30: =H30+J30 -> 45 | L30: =(F30/H30)*100 -> 100 | M30: =(G30/J30)*100 -> 100 | N30: =(I30/K30)*100 -> 100
A31: 19 | B31: UI23CS22 | C31: GAYATRI | D31: =Th_CSE_SDP!AP29 -> 34 | E31: =th_cse_ab!AC11 -> #REF! | F31: =D31 -> 34 | G31: =LAB_B1!O29 -> 10 | H31: =Th_CSE_SDP!AR29 -> 35 | I31: =SUM(F31:G31) -> 44 | J31: =LAB_B1!Q29 -> 10 | K31: =H31+J31 -> 45 | L31: =(F31/H31)*100 -> 97.142857 | M31: =(G31/J31)*100 -> 100 | N31: =(I31/K31)*100 -> 97.777778
A32: 20 | B32: UI23CS23 | C32: HARSH ASHOKBHAI ZADAFIYA | D32: =Th_CSE_SDP!AP30 -> 33 | E32: =th_cse_ab!AC11 -> #REF! | F32: =D32 -> 33 | G32: =LAB_B1!O30 -> 9 | H32: =Th_CSE_SDP!AR30 -> 35 | I32: =SUM(F32:G32) -> 42 | J32: =LAB_B1!Q30 -> 10 | K32: =H32+J32 -> 45 | L32: =(F32/H32)*100 -> 94.285714 | M32: =(G32/J32)*100 -> 90 | N32: =(I32/K32)*100 -> 93.333333
A33: 21 | B33: UI23CS24 | C33: HARSH SURESHBHAI PATEL | D33: =Th_CSE_SDP!AP31 -> 34 | E33: =th_cse_ab!AC11 -> #REF! | F33: =D33 -> 34 | G33: =LAB_B1!O31 -> 10 | H33: =Th_CSE_SDP!AR31 -> 35 | I33: =SUM(F33:G33) -> 44 | J33: =LAB_B1!Q31 -> 10 | K33: =H33+J33 -> 45 | L33: =(F33/H33)*100 -> 97.142857 | M33: =(G33/J33)*100 -> 100 | N33: =(I33/K33)*100 -> 97.777778
A34: 22 | B34: UI23CS25 | C34: HARSH VARDHAN SINGH | D34: =Th_CSE_SDP!AP32 -> 34 | E34: =th_cse_ab!AC11 -> #REF! | F34: =D34 -> 34 | G34: =LAB_B1!O32 -> 10 | H34: =Th_CSE_SDP!AR32 -> 35 | I34: =SUM(F34:G34) -> 44 | J34: =LAB_B1!Q32 -> 10 | K34: =H34+J34 -> 45 | L34: =(F34/H34)*100 -> 97.142857 | M34: =(G34/J34)*100 -> 100 | N34: =(I34/K34)*100 -> 97.777778
A35: 23 | B35: UI23CS26 | C35: HARSH KHULBE | D35: =Th_CSE_SDP!AP33 -> 31 | E35: =th_cse_ab!AC11 -> #REF! | F35: =D35 -> 31 | G35: =LAB_B1!O33 -> 9 | H35: =Th_CSE_SDP!AR33 -> 35 | I35: =SUM(F35:G35) -> 40 | J35: =LAB_B1!Q33 -> 10 | K35: =H35+J35 -> 45 | L35: =(F35/H35)*100 -> 88.571429 | M35: =(G35/J35)*100 -> 90 | N35: =(I35/K35)*100 -> 88.888889
A36: 24 | B36: UI23CS27 | C36: HARSH SINGH | D36: =Th_CSE_SDP!AP34 -> 35 | E36: =th_cse_ab!AC11 -> #REF! | F36: =D36 -> 35 | G36: =LAB_B1!O34 -> 9 | H36: =Th_CSE_SDP!AR34 -> 35 | I36: =SUM(F36:G36) -> 44 | J36: =LAB_B1!Q34 -> 10 | K36: =H36+J36 -> 45 | L36: =(F36/H36)*100 -> 100 | M36: =(G36/J36)*100 -> 90 | N36: =(I36/K36)*100 -> 97.777778
A37: 25 | B37: UI23CS28 | C37: HARSH SHARMA | D37: =Th_CSE_SDP!AP35 -> 34 | E37: =th_cse_ab!AC11 -> #REF! | F37: =D37 -> 34 | G37: =LAB_B1!O35 -> 9 | H37: =Th_CSE_SDP!AR35 -> 35 | I37: =SUM(F37:G37) -> 43 | J37: =LAB_B1!Q35 -> 10 | K37: =H37+J37 -> 45 | L37: =(F37/H37)*100 -> 97.142857 | M37: =(G37/J37)*100 -> 90 | N37: =(I37/K37)*100 -> 95.555556
A38: 26 | B38: UI23CS29 | C38: JASH KAPOOR | D38: =Th_CSE_SDP!AP36 -> 33 | E38: =th_cse_ab!AC11 -> #REF! | F38: =D38 -> 33 | G38: =LAB_B1!O36 -> 10 | H38: =Th_CSE_SDP!AR36 -> 35 | I38: =SUM(F38:G38) -> 43 | J38: =LAB_B1!Q36 -> 10 | K38: =H38+J38 -> 45 | L38: =(F38/H38)*100 -> 94.285714 | M38: =(G38/J38)*100 -> 100 | N38: =(I38/K38)*100 -> 95.555556
A39: 27 | B39: UI23CS30 | C39: JEEVANT | D39: =Th_CSE_SDP!AP37 -> 33 | E39: =th_cse_ab!AC11 -> #REF! | F39: =D39 -> 33 | G39: =LAB_B1!O37 -> 10 | H39: =Th_CSE_SDP!AR37 -> 35 | I39: =SUM(F39:G39) -> 43 | J39: =LAB_B1!Q37 -> 10 | K39: =H39+J39 -> 45 | L39: =(F39/H39)*100 -> 94.285714 | M39: =(G39/J39)*100 -> 100 | N39: =(I39/K39)*100 -> 95.555556
A40: 28 | B40: UI23CS31 | C40: KALPANA SINGH | D40: =Th_CSE_SDP!AP38 -> 34 | E40: =th_cse_ab!AC11 -> #REF! | F40: =D40 -> 34 | G40: =LAB_B1!O38 -> 9 | H40: =Th_CSE_SDP!AR38 -> 35 | I40: =SUM(F40:G40) -> 43 | J40: =LAB_B1!Q38 -> 10 | K40: =H40+J40 -> 45 | L40: =(F40/H40)*100 -> 97.142857 | M40: =(G40/J40)*100 -> 90 | N40: =(I40/K40)*100 -> 95.555556
A41: 29 | B41: UI23CS32 | C41: KAPIL YADAV | D41: =Th_CSE_SDP!AP39 -> 34 | E41: =th_cse_ab!AC11 -> #REF! | F41: =D41 -> 34 | G41: =LAB_B1!O39 -> 10 | H41: =Th_CSE_SDP!AR39 -> 35 | I41: =SUM(F41:G41) -> 44 | J41: =LAB_B1!Q39 -> 10 | K41: =H41+J41 -> 45 | L41: =(F41/H41)*100 -> 97.142857 | M41: =(G41/J41)*100 -> 100 | N41: =(I41/K41)*100 -> 97.777778
A42: 30 | B42: UI23CS33 | C42: KARTIK RAJ | D42: =Th_CSE_SDP!AP40 -> 34 | E42: =th_cse_ab!AC11 -> #REF! | F42: =D42 -> 34 | G42: =LAB_B1!O40 -> 10 | H42: =Th_CSE_SDP!AR40 -> 35 | I42: =SUM(F42:G42) -> 44 | J42: =LAB_B1!Q40 -> 10 | K42: =H42+J42 -> 45 | L42: =(F42/H42)*100 -> 97.142857 | M42: =(G42/J42)*100 -> 100 | N42: =(I42/K42)*100 -> 97.777778
A43: 31 | B43: UI23CS34 | C43: KAVYA ASHOKBHAI PATEL | D43: =Th_CSE_SDP!AP41 -> 35 | E43: =th_cse_ab!AC11 -> #REF! | F43: =D43 -> 35 | G43: =LAB_B1!O41 -> 10 | H43: =Th_CSE_SDP!AR41 -> 35 | I43: =SUM(F43:G43) -> 45 | J43: =LAB_B1!Q41 -> 10 | K43: =H43+J43 -> 45 | L43: =(F43/H43)*100 -> 100 | M43: =(G43/J43)*100 -> 100 | N43: =(I43/K43)*100 -> 100
A44: 32 | B44: UI23CS35 | C44: KSHITIJ AMITBHAI PATEL | D44: =Th_CSE_SDP!AP42 -> 34 | E44: =th_cse_ab!AC11 -> #REF! | F44: =D44 -> 34 | G44: =LAB_B1!O42 -> 10 | H44: =Th_CSE_SDP!AR42 -> 35 | I44: =SUM(F44:G44) -> 44 | J44: =LAB_B1!Q42 -> 10 | K44: =H44+J44 -> 45 | L44: =(F44/H44)*100 -> 97.142857 | M44: =(G44/J44)*100 -> 100 | N44: =(I44/K44)*100 -> 97.777778
...

Sheet CSE Less than 75%
A1: Indian Institute of Information Technology (IIIT), Surat
A2: Computer Science and Engineering Department
A3: B.Tech - II Semester - V
A4: Subject Name: Data Science - (CS501)
A5: Subject Coordinator: Mr Anandatheertan Srinivasan
A6: Academic Year: 2025-2026
D7: Attended_Lec_SDP | E7: Attended_Lec_AB | F7: Total_Attended_Lec | G7: Attended_Lab | H7: Total Lec | I7: Total_Attendance | J7: Total Lab | K7: Total_Lec_Lab | L7: Present Percentage Theory (%) | M7: Present Percentage Lab (%) | N7: Present Percentage (%)
A10: =IFERROR(__xludf.DUMMYFUNCTION("FILTER(Total_CSE!A13:N97,Total_CSE!N13:N97 <75)"),"#REF!") -> #REF! | B10: ="COMPUTED_VALUE" -> COMPUTED_VALUE | C10: ="COMPUTED_VALUE" -> COMPUTED_VALUE | D10: ="COMPUTED_VALUE" -> COMPUTED_VALUE | E10: ="COMPUTED_VALUE" -> COMPUTED_VALUE | F10: ="COMPUTED_VALUE" -> COMPUTED_VALUE | G10: ="COMPUTED_VALUE" -> COMPUTED_VALUE | H10: ="COMPUTED_VALUE" -> COMPUTED_VALUE | I10: ="COMPUTED_VALUE" -> COMPUTED_VALUE | ... N10: ="COMPUTED_VALUE" -> COMPUTED_VALUE
A11: ="COMPUTED_VALUE" -> COMPUTED_VALUE | B11: ="COMPUTED_VALUE" -> COMPUTED_VALUE | C11: ="COMPUTED_VALUE" -> COMPUTED_VALUE | D11: ="COMPUTED_VALUE" -> COMPUTED_VALUE | E11: ="COMPUTED_VALUE" -> COMPUTED_VALUE | F11: ="COMPUTED_VALUE" -> COMPUTED_VALUE | G11: ="COMPUTED_VALUE" -> COMPUTED_VALUE | H11: ="COMPUTED_VALUE" -> COMPUTED_VALUE | ... N11: ="COMPUTED_VALUE" -> COMPUTED_VALUE
A12: ="COMPUTED_VALUE" -> COMPUTED_VALUE | B12: ="COMPUTED_VALUE" -> COMPUTED_VALUE | C12: ="COMPUTED_VALUE" -> COMPUTED_VALUE | D12: ="COMPUTED_VALUE" -> COMPUTED_VALUE | E12: ="COMPUTED_VALUE" -> COMPUTED_VALUE | F12: ="COMPUTED_VALUE" -> COMPUTED_VALUE | G12: ="COMPUTED_VALUE" -> COMPUTED_VALUE | H12: ="COMPUTED_VALUE" -> COMPUTED_VALUE | ... N12: ="COMPUTED_VALUE" -> COMPUTED_VALUE
A13: ="COMPUTED_VALUE" -> COMPUTED_VALUE | B13: ="COMPUTED_VALUE" -> COMPUTED_VALUE | C13: ="COMPUTED_VALUE" -> COMPUTED_VALUE | D13: ="COMPUTED_VALUE" -> COMPUTED_VALUE | E13: ="COMPUTED_VALUE" -> COMPUTED_VALUE | F13: ="COMPUTED_VALUE" -> COMPUTED_VALUE | G13: ="COMPUTED_VALUE" -> COMPUTED_VALUE | H13: ="COMPUTED_VALUE" -> COMPUTED_VALUE | ... N13: ="COMPUTED_VALUE" -> COMPUTED_VALUE
A14: ="COMPUTED_VALUE" -> COMPUTED_VALUE | B14: ="COMPUTED_VALUE" -> COMPUTED_VALUE | C14: ="COMPUTED_VALUE" -> COMPUTED_VALUE | D14: ="COMPUTED_VALUE" -> COMPUTED_VALUE | E14: ="COMPUTED_VALUE" -> COMPUTED_VALUE | F14: ="COMPUTED_VALUE" -> COMPUTED_VALUE | G14: ="COMPUTED_VALUE" -> COMPUTED_VALUE | H14: ="COMPUTED_VALUE" -> COMPUTED_VALUE | ... N14: ="COMPUTED_VALUE" -> COMPUTED_VALUE
A15: ="COMPUTED_VALUE" -> COMPUTED_VALUE | B15: ="COMPUTED_VALUE" -> COMPUTED_VALUE | C15: ="COMPUTED_VALUE" -> COMPUTED_VALUE | D15: ="COMPUTED_VALUE" -> COMPUTED_VALUE | E15: ="COMPUTED_VALUE" -> COMPUTED_VALUE | F15: ="COMPUTED_VALUE" -> COMPUTED_VALUE | G15: ="COMPUTED_VALUE" -> COMPUTED_VALUE | H15: ="COMPUTED_VALUE" -> COMPUTED_VALUE | ... N15: ="COMPUTED_VALUE" -> COMPUTED_VALUE
A16: ="COMPUTED_VALUE" -> COMPUTED_VALUE | B16: ="COMPUTED_VALUE" -> COMPUTED_VALUE | C16: ="COMPUTED_VALUE" -> COMPUTED_VALUE | D16: ="COMPUTED_VALUE" -> COMPUTED_VALUE | E16: ="COMPUTED_VALUE" -> COMPUTED_VALUE | F16: ="COMPUTED_VALUE" -> COMPUTED_VALUE | G16: ="COMPUTED_VALUE" -> COMPUTED_VALUE | H16: ="COMPUTED_VALUE" -> COMPUTED_VALUE | ... N16: ="COMPUTED_VALUE" -> COMPUTED_VALUE
A17: ="COMPUTED_VALUE" -> COMPUTED_VALUE | B17: ="COMPUTED_VALUE" -> COMPUTED_VALUE | C17: ="COMPUTED_VALUE" -> COMPUTED_VALUE | D17: ="COMPUTED_VALUE" -> COMPUTED_VALUE | E17: ="COMPUTED_VALUE" -> COMPUTED_VALUE | F17: ="COMPUTED_VALUE" -> COMPUTED_VALUE | G17: ="COMPUTED_VALUE" -> COMPUTED_VALUE | H17: ="COMPUTED_VALUE" -> COMPUTED_VALUE | ... N17: ="COMPUTED_VALUE" -> COMPUTED_VALUE
A18: ="COMPUTED_VALUE" -> COMPUTED_VALUE | B18: ="COMPUTED_VALUE" -> COMPUTED_VALUE | C18: ="COMPUTED_VALUE" -> COMPUTED_VALUE | D18: ="COMPUTED_VALUE" -> COMPUTED_VALUE | E18: ="COMPUTED_VALUE" -> COMPUTED_VALUE | F18: ="COMPUTED_VALUE" -> COMPUTED_VALUE | G18: ="COMPUTED_VALUE" -> COMPUTED_VALUE | H18: ="COMPUTED_VALUE" -> COMPUTED_VALUE | ... N18: ="COMPUTED_VALUE" -> COMPUTED_VALUE
A19: ="COMPUTED_VALUE" -> COMPUTED_VALUE | B19: ="COMPUTED_VALUE" -> COMPUTED_VALUE | C19: ="COMPUTED_VALUE" -> COMPUTED_VALUE | D19: ="COMPUTED_VALUE" -> COMPUTED_VALUE | E19: ="COMPUTED_VALUE" -> COMPUTED_VALUE | F19: ="COMPUTED_VALUE" -> COMPUTED_VALUE | G19: ="COMPUTED_VALUE" -> COMPUTED_VALUE | H19: ="COMPUTED_VALUE" -> COMPUTED_VALUE | ... N19: ="COMPUTED_VALUE" -> COMPUTED_VALUE
A20: ="COMPUTED_VALUE" -> COMPUTED_VALUE | B20: ="COMPUTED_VALUE" -> COMPUTED_VALUE | C20: ="COMPUTED_VALUE" -> COMPUTED_VALUE | D20: ="COMPUTED_VALUE" -> COMPUTED_VALUE | E20: ="COMPUTED_VALUE" -> COMPUTED_VALUE | F20: ="COMPUTED_VALUE" -> COMPUTED_VALUE | G20: ="COMPUTED_VALUE" -> COMPUTED_VALUE | H20: ="COMPUTED_VALUE" -> COMPUTED_VALUE | ... N20: ="COMPUTED_VALUE" -> COMPUTED_VALUE
A21: ="COMPUTED_VALUE" -> COMPUTED_VALUE | B21: ="COMPUTED_VALUE" -> COMPUTED_VALUE | C21: ="COMPUTED_VALUE" -> COMPUTED_VALUE | D21: ="COMPUTED_VALUE" -> COMPUTED_VALUE | E21: ="COMPUTED_VALUE" -> COMPUTED_VALUE | F21: ="COMPUTED_VALUE" -> COMPUTED_VALUE | G21: ="COMPUTED_VALUE" -> COMPUTED_VALUE | H21: ="COMPUTED_VALUE" -> COMPUTED_VALUE | ... N21: ="COMPUTED_VALUE" -> COMPUTED_VALUE
A22: ="COMPUTED_VALUE" -> COMPUTED_VALUE | B22: ="COMPUTED_VALUE" -> COMPUTED_VALUE | C22: ="COMPUTED_VALUE" -> COMPUTED_VALUE | D22: ="COMPUTED_VALUE" -> COMPUTED_VALUE | E22: ="COMPUTED_VALUE" -> COMPUTED_VALUE | F22: ="COMPUTED_VALUE" -> COMPUTED_VALUE | G22: ="COMPUTED_VALUE" -> COMPUTED_VALUE | H22: ="COMPUTED_VALUE" -> COMPUTED_VALUE | ... N22: ="COMPUTED_VALUE" -> COMPUTED_VALUE
... A40: ="COMPUTED_VALUE" -> COMPUTED_VALUE | B40: ="COMPUTED_VALUE" -> COMPUTED_VALUE | C40: ="COMPUTED_VALUE" -> COMPUTED_VALUE | D40: ="COMPUTED_VALUE" -> COMPUTED_VALUE | E40: ="COMPUTED_VALUE" -> COMPUTED_VALUE | F40: ="COMPUTED_VALUE" -> COMPUTED_VALUE | G40: ="COMPUTED_VALUE" -> COMPUTED_VALUE | H40: ="COMPUTED_VALUE" -> COMPUTED_VALUE | ... N40: ="COMPUTED_VALUE" -> COMPUTED_VALUE
A41: ="COMPUTED_VALUE" -> COMPUTED_VALUE
A42: ="COMPUTED_VALUE" -> COMPUTED_VALUE
A43: ="COMPUTED_VALUE" -> COMPUTED_VALUE
A44: ="COMPUTED_VALUE" -> COMPUTED_VALUE
A45: ="COMPUTED_VALUE" -> COMPUTED_VALUE
A46: ="COMPUTED_VALUE" -> COMPUTED_VALUE
A47: ="COMPUTED_VALUE" -> COMPUTED_VALUE
A48: ="COMPUTED_VALUE" -> COMPUTED_VALUE
A49: ="COMPUTED_VALUE" -> COMPUTED_VALUE
A50: ="COMPUTED_VALUE" -> COMPUTED_VALUE
A51: ="COMPUTED_VALUE" -> COMPUTED_VALUE
